Workbook

Sheet Summary
A1: GRC Lab 1 - Risk Assessment Summary
A2: Target 192.168.164.129 (Metasploitable test server) | Scans 22 Oct 2026 | All counts are live formulas over the Risk Register
A4: Findings by inherent risk | F4: Nuclei results by severity (raw scanner output)
A5: Inherent risk | B5: Findings | C5: % of total | D5: Lab rating (H/M/L) | F5: Nuclei severity | G5: Results | H5: % of total
A6: ='Scoring & Notes'!A34 -> Critical | B6: =COUNTIF('Risk Register'!$R$2:$R$39,A6) -> 6 | C6: =IF($B$10=0,0,B6/$B$10) -> 0.15789474 | D6: H | F6: Critical | G6: =COUNTIF('Nuclei Results'!$D$5:$D$200,F6) -> 4 | H6: =IF($G$11=0,0,G6/$G$11) -> 0.06779661
A7: ='Scoring & Notes'!A35 -> High | B7: =COUNTIF('Risk Register'!$R$2:$R$39,A7) -> 14 | C7: =IF($B$10=0,0,B7/$B$10) -> 0.36842105 | D7: H | F7: High | G7: =COUNTIF('Nuclei Results'!$D$5:$D$200,F7) -> 18 | H7: =IF($G$11=0,0,G7/$G$11) -> 0.30508475
A8: ='Scoring & Notes'!A36 -> Medium | B8: =COUNTIF('Risk Register'!$R$2:$R$39,A8) -> 10 | C8: =IF($B$10=0,0,B8/$B$10) -> 0.26315789 | D8: M | F8: Medium | G8: =COUNTIF('Nuclei Results'!$D$5:$D$200,F8) -> 2 | H8: =IF($G$11=0,0,G8/$G$11) -> 0.033898305
A9: ='Scoring & Notes'!A37 -> Low | B9: =COUNTIF('Risk Register'!$R$2:$R$39,A9) -> 8 | C9: =IF($B$10=0,0,B9/$B$10) -> 0.21052632 | D9: L | F9: Low | G9: =COUNTIF('Nuclei Results'!$D$5:$D$200,F9) -> 2 | H9: =IF($G$11=0,0,G9/$G$11) -> 0.033898305
A10: Total findings | B10: =SUM(B6:B9) -> 38 | C10: =SUM(C6:C9) -> 1 | F10: Info | G10: =COUNTIF('Nuclei Results'!$D$5:$D$200,F10) -> 33 | H10: =IF($G$11=0,0,G10/$G$11) -> 0.55932203
A11: Check: rows in register | B11: =COUNTA('Risk Register'!$A$2:$A$39) -> 38 | F11: Total Nuclei results | G11: =SUM(G6:G10) -> 59 | H11: =SUM(H6:H10) -> 1
A13: Lab rating (H/M/L) | F13: Attack surface (Nmap -p-)
A14: Lab rating | B14: Findings | C14: % of total | F14: Measure | G14: Count
A15: H | B15: =COUNTIF('Risk Register'!$S$2:$S$39,A15) -> 20 | C15: =IF($B$10=0,0,B15/$B$10) -> 0.52631579 | F15: Ports scanned | G15: 65535
A16: M | B16: =COUNTIF('Risk Register'!$S$2:$S$39,A16) -> 10 | C16: =IF($B$10=0,0,B16/$B$10) -> 0.26315789 | F16: Open TCP ports | G16: =COUNTA('Open Ports'!$A$5:$A$100) -> 30
A17: L | B17: =COUNTIF('Risk Register'!$S$2:$S$39,A17) -> 8 | C17: =IF($B$10=0,0,B17/$B$10) -> 0.21052632 | F17: Closed (reset) | G17: =G15-G16-G18 -> 65505
F18: Filtered | G18: 0
A19: Remediation status
A20: Status | B20: Findings | C20: % of total | F20: Nikto items reported | G20: =COUNTA('Nikto Results'!$A$5:$A$100) -> 27
A21: Open | B21: =COUNTIF('Risk Register'!$AG$2:$AG$39,A21) -> 38 | C21: =IF($B$10=0,0,B21/$B$10) -> 1
A22: In progress | B22: =COUNTIF('Risk Register'!$AG$2:$AG$39,A22) -> 0 | C22: =IF($B$10=0,0,B22/$B$10) -> 0
A23: Remediated | B23: =COUNTIF('Risk Register'!$AG$2:$AG$39,A23) -> 0 | C23: =IF($B$10=0,0,B23/$B$10) -> 0
A24: Validated closed | B24: =COUNTIF('Risk Register'!$AG$2:$AG$39,A24) -> 0 | C24: =IF($B$10=0,0,B24/$B$10) -> 0
A25: Risk accepted | B25: =COUNTIF('Risk Register'!$AG$2:$AG$39,A25) -> 0 | C25: =IF($B$10=0,0,B25/$B$10) -> 0
A27: Critical findings requiring immediate action (P1)
A28: Finding | B28: ID | C28: Score | D28: Port
A29: ='Risk Register'!C2 -> vsftpd 2.3.4 backdoor detected | B29: ='Risk Register'!A2 -> R01 | C29: ='Risk Register'!Q2 -> 25 | D29: ='Risk Register'!F2 -> TCP/21 (backdoor shell TCP/6200)
A30: ='Risk Register'!C3 -> Bind shell identified as 'Metasploitable root shell' | B30: ='Risk Register'!A3 -> R02 | C30: ='Risk Register'!Q3 -> 25 | D30: ='Risk Register'!F3 -> TCP/1524
A31: ='Risk Register'!C4 -> PostgreSQL accessible with empty and default credentials | B31: ='Risk Register'!A4 -> R03 | C31: ='Risk Register'!Q4 -> 20 | D31: ='Risk Register'!F4 -> TCP/5432
A32: ='Risk Register'!C5 -> Apache JServ (AJP) 'Ghostcat' vulnerability | B32: ='Risk Register'!A5 -> R04 | C32: ='Risk Register'!Q5 -> 20 | D32: ='Risk Register'!F5 -> TCP/8009
A33: ='Risk Register'!C6 -> distccd remote command execution | B33: ='Risk Register'!A6 -> R05 | C33: ='Risk Register'!Q6 -> 20 | D33: ='Risk Register'!F6 -> TCP/3632
A34: ='Risk Register'!C7 -> VNC remote desktop with weak password and weak protocol | B34: ='Risk Register'!A7 -> R06 | C34: ='Risk Register'!Q7 -> 20 | D34: ='Risk Register'!F7 -> TCP/5900
A36: Note: counts of Critical are driven by the Likelihood x Impact scores and thresholds on 'Scoring & Notes'. Edit those blue inputs and this page recalculates.

Sheet Compliance Mapping
A2: Suggested control alignments for each finding (references to the Risk Register). Not a formal finding of non-compliance; apply PCI DSS only if in scope.
A4: ID | B4: Finding | C4: Inherent risk | D4: CIS Controls v8 | E4: NIST CSF 2.0 | F4: ISO/IEC 27001:2022 | G4: PCI DSS v4.0 (if in scope) | H4: OWASP Top 10 2021
A5: ='Risk Register'!A2 -> R01 | B5: ='Risk Register'!C2 -> vsftpd 2.3.4 backdoor detected | C5: ='Risk Register'!R2 -> Critical | D5: ='Risk Register'!V2 -> CIS 7.1, 7.4, 7.7 | E5: ='Risk Register'!W2 -> ID.RA-01; PR.PS-02 | F5: ='Risk Register'!X2 -> A.8.8 | G5: ='Risk Register'!Y2 -> Req. 6.3.1, 6.3.3 | H5: ='Risk Register'!Z2 -> A06:2021 Vulnerable and Outdated Components
A6: ='Risk Register'!A3 -> R02 | B6: ='Risk Register'!C3 -> Bind shell identified as 'Metasploitable root shell' | C6: ='Risk Register'!R3 -> Critical | D6: ='Risk Register'!V3 -> CIS 4.1, 4.8 | E6: ='Risk Register'!W3 -> PR.PS-01 | F6: ='Risk Register'!X3 -> A.8.9 | G6: ='Risk Register'!Y3 -> Req. 2.2.4 | H6: ='Risk Register'!Z3 -> A05:2021 Security Misconfiguration
A7: ='Risk Register'!A4 -> R03 | B7: ='Risk Register'!C4 -> PostgreSQL accessible with empty and default credentials | C7: ='Risk Register'!R4 -> Critical | D7: ='Risk Register'!V4 -> CIS 4.7, 5.2, 6.1 | E7: ='Risk Register'!W4 -> PR.AA-01; PR.AA-03 | F7: ='Risk Register'!X4 -> A.5.17; A.8.5 | G7: ='Risk Register'!Y4 -> Req. 2.2.2, 8.3.1, 8.3.6 | H7: ='Risk Register'!Z4 -> A07:2021 Identification and Authentication Failures
A8: ='Risk Register'!A5 -> R04 | B8: ='Risk Register'!C5 -> Apache JServ (AJP) 'Ghostcat' vulnerability | C8: ='Risk Register'!R5 -> Critical | D8: ='Risk Register'!V5 -> CIS 7.1, 7.4, 7.7 | E8: ='Risk Register'!W5 -> ID.RA-01; PR.PS-02 | F8: ='Risk Register'!X5 -> A.8.8 | G8: ='Risk Register'!Y5 -> Req. 6.3.1, 6.3.3 | H8: ='Risk Register'!Z5 -> A06:2021 Vulnerable and Outdated Components
A9: ='Risk Register'!A6 -> R05 | B9: ='Risk Register'!C6 -> distccd remote command execution | C9: ='Risk Register'!R6 -> Critical | D9: ='Risk Register'!V6 -> CIS 4.1, 4.8 | E9: ='Risk Register'!W6 -> PR.PS-01 | F9: ='Risk Register'!X6 -> A.8.9 | G9: ='Risk Register'!Y6 -> Req. 2.2.4 | H9: ='Risk Register'!Z6 -> A05:2021 Security Misconfiguration
A10: ='Risk Register'!A7 -> R06 | B10: ='Risk Register'!C7 -> VNC remote desktop with weak password and weak protocol | C10: ='Risk Register'!R7 -> Critical | D10: ='Risk Register'!V7 -> CIS 4.7, 5.2, 6.1 | E10: ='Risk Register'!W7 -> PR.AA-01; PR.AA-03 | F10: ='Risk Register'!X7 -> A.5.17; A.8.5 | G10: ='Risk Register'!Y7 -> Req. 2.2.2, 8.3.1, 8.3.6 | H10: ='Risk Register'!Z7 -> A07:2021 Identification and Authentication Failures
A11: ='Risk Register'!A8 -> R07 | B11: ='Risk Register'!C8 -> UnrealIRCd 3.2.8.1 (release known to have been trojaned) | C11: ='Risk Register'!R8 -> High | D11: ='Risk Register'!V8 -> CIS 7.1, 7.4, 7.7 | E11: ='Risk Register'!W8 -> ID.RA-01; PR.PS-02 | F11: ='Risk Register'!X8 -> A.8.8 | G11: ='Risk Register'!Y8 -> Req. 6.3.1, 6.3.3 | H11: ='Risk Register'!Z8 -> A06:2021 Vulnerable and Outdated Components
A12: ='Risk Register'!A9 -> R08 | B12: ='Risk Register'!C9 -> Telnet service exposed (cleartext remote login) | C12: ='Risk Register'!R9 -> High | D12: ='Risk Register'!V9 -> CIS 3.10, 12.6 | E12: ='Risk Register'!W9 -> PR.DS-02 | F12: ='Risk Register'!X9 -> A.8.24; A.5.14 | G12: ='Risk Register'!Y9 -> Req. 2.2.7, 4.2.1 | H12: ='Risk Register'!Z9 -> A02:2021 Cryptographic Failures
A13: ='Risk Register'!A10 -> R09 | B13: ='Risk Register'!C10 -> Legacy r-services exposed (rexec, rlogin, rsh) | C13: ='Risk Register'!R10 -> High | D13: ='Risk Register'!V10 -> CIS 3.10, 12.6 | E13: ='Risk Register'!W10 -> PR.DS-02 | F13: ='Risk Register'!X10 -> A.8.24; A.5.14 | G13: ='Risk Register'!Y10 -> Req. 2.2.7, 4.2.1 | H13: ='Risk Register'!Z10 -> A02:2021 Cryptographic Failures
A14: ='Risk Register'!A11 -> R10 | B14: ='Risk Register'!C11 -> Anonymous FTP login and weak FTP credentials | C14: ='Risk Register'!R11 -> High | D14: ='Risk Register'!V11 -> CIS 4.7, 5.2, 6.1 | E14: ='Risk Register'!W11 -> PR.AA-01; PR.AA-03 | F14: ='Risk Register'!X11 -> A.5.17; A.8.5 | G14: ='Risk Register'!Y11 -> Req. 2.2.2, 8.3.1, 8.3.6 | H14: ='Risk Register'!Z11 -> A07:2021 Identification and Authentication Failures
A15: ='Risk Register'!A12 -> R11 | B15: ='Risk Register'!C12 -> Samba 3.0.20 flagged for CVE-2026-4480 (version-based) | C15: ='Risk Register'!R12 -> High | D15: ='Risk Register'!V12 -> CIS 7.1, 7.4, 7.7 | E15: ='Risk Register'!W12 -> ID.RA-01; PR.PS-02 | F15: ='Risk Register'!X12 -> A.8.8 | G15: ='Risk Register'!Y12 -> Req. 6.3.1, 6.3.3 | H15: ='Risk Register'!Z12 -> A06:2021 Vulnerable and Outdated Components
A16: ='Risk Register'!A13 -> R12 | B16: ='Risk Register'!C13 -> SMB weaknesses: SMBv1, guest access and signing disabled | C16: ='Risk Register'!R13 -> High | D16: ='Risk Register'!V13 -> CIS 3.3, 6.1, 6.8 | E16: ='Risk Register'!W13 -> PR.AA-05 | F16: ='Risk Register'!X13 -> A.5.15; A.8.3 | G16: ='Risk Register'!Y13 -> Req. 7.2 | H16: ='Risk Register'!Z13 -> A01:2021 Broken Access Control
... A42: ='Risk Register'!A39 -> R38 | B42: ='Risk Register'!C39 -> NetBIOS and RPC information disclosure | C42: ='Risk Register'!R39 -> Low | D42: ='Risk Register'!V39 -> CIS 16.7, 4.1 | E42: ='Risk Register'!W39 -> PR.PS-01 | F42: ='Risk Register'!X39 -> A.8.9 | G42: ='Risk Register'!Y39 -> Req. 6.2.4 | H42: ='Risk Register'!Z39 -> A05:2021 Security Misconfiguration (CWE-200)
A44: Framework legend and lab-brief cross-reference
B45: CIS Controls v8 | C45: Safeguards cited: 1.1 asset inventory; 2.2 supported software; 3.3 data access control lists; 3.10 encrypt data in transit; 4.1 secure configuration process; 4.4 server firewall; 4.7 manage default accounts; 4.8 disable unnecessary services; 5.2 unique passwords; 6.1 / 6.8 access granting and RBAC; 7.1 / 7.4 / 7.7 vulnerability and patch management; 8.4 time synchronisation; 12.2 secure network architecture; 12.6 secure management protocols; 13.4 traffic filtering; 16.7 hardening templates.
B46: NIST CSF 2.0 | C46: ID.AM-01 asset inventory; ID.RA-01 vulnerabilities identified and validated; PR.AA-01/03/05 identities, authentication and least privilege; PR.DS-02 data in transit; PR.IR-01 network protection; PR.PS-01 configuration management; PR.PS-02 software maintained and replaced; PR.PS-04 log records generated.
B47: ISO/IEC 27001:2022 Annex A | C47: A.5.9 inventory; A.5.15 access control; A.5.17 authentication information; A.8.3 information access restriction; A.8.5 secure authentication; A.8.8 technical vulnerability management; A.8.9 configuration management; A.8.17 clock synchronisation; A.8.19 software installation; A.8.20 network security; A.8.22 segregation of networks; A.8.24 cryptography; A.8.26 application security requirements.
B48: PCI DSS v4.0 | C48: Req. 1 network controls; 2.2.x secure configuration (2.2.2 vendor defaults, 2.2.4 only necessary services, 2.2.7 encrypted admin access); 4.2.1 strong cryptography in transit; 6.2 / 6.3 secure software and patching; 7.2 access control; 8.3 authentication; 10.6 time synchronisation. Only applicable if the host is in the cardholder-data environment.
B49: Lab-brief cross-reference | C49: Lab text cites CIS Control 9 (v7 'Limitation and Control of Network Ports, Protocols and Services') = v8 safeguards 4.8 and 12.2/13.4; NIST CSF 1.1 ID.AM-1 = CSF 2.0 ID.AM-01; PR.IP-1 = PR.PS-01; PR.DS-2 = PR.DS-02; PR.AC-1 = PR.AA-01; CIS 7.1 = vulnerability management process (7.1 in v8).

Sheet Risk Register
A1: ID | B1: Previous ID (v1) | C1: Finding | D1: Description | E1: Affected service | F1: Port / protocol | G1: Detected by | H1: CVE/reference | I1: CVSS / external severity | J1: Scanner severity | K1: Evidence/status | L1: Status / validation | M1: Likelihood (1-5) | N1: Likelihood label | O1: Impact (1-5) | P1: Impact label | Q1: Risk score (L x I) | R1: Inherent risk | S1: Lab rating (H/M/L) | T1: Priority | U1: Business impact | V1: CIS Controls v8 | W1: NIST CSF 2.0 | X1: ISO/IEC 27001:2022 | Y1: PCI DSS v4.0 (if in scope) | Z1: OWASP Top 10 2021 | AA1: Recommended action - immediate | AB1: Recommended action - long-term | AC1: Validation note | AD1: Suggested owner | AE1: Remediation SLA (days) | AF1: Target date | AG1: Remediation status | AH1: Comments / evidence of closure
A2: R01 | B2: R01 | C2: vsftpd 2.3.4 backdoor detected | D2: The vsftpd 2.3.4 source package downloaded between 30 June and 3 July 2011 contained a malicious backdoor (NVD): a login name ending in ':)' opens a root command shell on TCP/6200. The Nuclei template reported a match on that port, so this is stronger evidence than a banner alone. | E2: FTP - vsftpd 2.3.4 | F2: TCP/21 (backdoor shell TCP/6200) | G2: Nmap; Nuclei | H2: CVE-2011-2523 | I2: 9.8 Critical (CVSS v3.1, NVD); 10.0 (CVSS v2) | J2: Critical | K2: Nmap -sV banner 'vsftpd 2.3.4' on TCP/21. Nuclei template CVE-2011-2523 [tcp] [critical] matched 192.168.164.129:6200. | L2: Detected by Nuclei template (CVE-2011-2523, matched on TCP/6200); manual confirmation recommended | M2: 5 | N2: {=INDEX('Scoring & Notes'!$B$18:$B$22,MATCH(M2,'Scoring & Notes'!$A$18:$A$22,0))} -> Almost certain | O2: 5 | P2: {=INDEX('Scoring & Notes'!$B$26:$B$30,MATCH(O2,'Scoring & Notes'!$A$26:$A$30,0))} -> Severe | Q2: =M2*O2 -> 25 | R2: =IF(Q2>='Scoring & Notes'!$B$34,'Scoring & Notes'!$A$34,IF(Q2>='Scoring & Notes'!$B$35,'Scoring & Notes'!$A$35,IF(Q2>='Scoring & Notes'!$B$36,'Scoring & Notes'!$A$36,'Scoring & Notes'!$A$37))) -> Critical | S2: =IF(OR(R2='Scoring & Notes'!$A$34,R2='Scoring & Notes'!$A$35),"H",IF(R2='Scoring & Notes'!$A$36,"M","L")) -> H | T2: {=INDEX('Scoring & Notes'!$D$34:$D$37,MATCH(R2,'Scoring & Notes'!$A$34:$A$37,0))} -> P1 | U2: Unauthenticated remote root-level command execution leading to full host compromise, data theft, and use of the host as a pivot point. | V2: CIS 7.1, 7.4, 7.7 | W2: ID.RA-01; PR.PS-02 | X2: A.8.8 | Y2: Req. 6.3.1, 6.3.3 | Z2: A06:2021 Vulnerable and Outdated Components | AA2: Stop and disable vsftpd; isolate the host from other networks; confirm the finding in the lab (connect to TCP/6200 after triggering) only under instructor approval. | AB2: Remove the trojaned package; reinstall vsftpd from a trusted, signed repository at a supported version (or use SFTP); rebuild the host if integrity cannot be assured. | AC2: Template-based detection. Treat as confirmed for lab purposes; document manual confirmation if performed. | AD2: System administrator | AE2: {=INDEX('Scoring & Notes'!$E$34:$E$37,MATCH(R2,'Scoring & Notes'!$A$34:$A$37,0))} -> 7 | AF2: ='Scoring & Notes'!$B$12+AE2 -> 46325 | AG2: Open
A3: R02 | B3: R07 | C3: Bind shell identified as 'Metasploitable root shell' | D3: A listening service on TCP/1524 is identified by Nmap as a root shell that accepts connections without authentication (a bind shell). Such services are a hallmark of a deliberately planted backdoor. | E3: bindshell | F3: TCP/1524 | G3: Nmap | H3: Nmap service identification (no CVE) | I3: Not scored | J3: n/a | K3: Nmap: '1524/tcp open bindshell Metasploitable root shell'. | L3: Observed (Nmap -sV service identification); no interactive session opened | M3: 5 | N3: {=INDEX('Scoring & Notes'!$B$18:$B$22,MATCH(M3,'Scoring & Notes'!$A$18:$A$22,0))} -> Almost certain | O3: 5 | P3: {=INDEX('Scoring & Notes'!$B$26:$B$30,MATCH(O3,'Scoring & Notes'!$A$26:$A$30,0))} -> Severe | Q3: =M3*O3 -> 25 | R3: =IF(Q3>='Scoring & Notes'!$B$34,'Scoring & Notes'!$A$34,IF(Q3>='Scoring & Notes'!$B$35,'Scoring & Notes'!$A$35,IF(Q3>='Scoring & Notes'!$B$36,'Scoring & Notes'!$A$36,'Scoring & Notes'!$A$37))) -> Critical | S3: =IF(OR(R3='Scoring & Notes'!$A$34,R3='Scoring & Notes'!$A$35),"H",IF(R3='Scoring & Notes'!$A$36,"M","L")) -> H | T3: {=INDEX('Scoring & Notes'!$D$34:$D$37,MATCH(R3,'Scoring & Notes'!$A$34:$A$37,0))} -> P1 | U3: Direct, unauthenticated privileged access to the operating system; complete loss of confidentiality, integrity and availability. | V3: CIS 4.1, 4.8 | W3: PR.PS-01 | X3: A.8.9 | Y3: Req. 2.2.4 | Z3: A05:2021 Security Misconfiguration | AA3: Identify and kill the listening process; block TCP/1524 at host and network level; keep host isolated. | AB3: Investigate how the listener is started (inetd/xinetd, init scripts); remove; add a host firewall default-deny policy; monitor for new listeners. | AC3: Service identity comes from Nmap fingerprinting. Confirm by process inspection on the host. | AD3: System administrator | AE3: {=INDEX('Scoring & Notes'!$E$34:$E$37,MATCH(R3,'Scoring & Notes'!$A$34:$A$37,0))} -> 7 | AF3: ='Scoring & Notes'!$B$12+AE3 -> 46325 | AG3: Open
A4: R03 | B4: R06 (part) | C4: PostgreSQL accessible with empty and default credentials | D4: The database superuser account 'postgres' accepts an empty password and the well-known default password 'postgres'. The network listener is reachable from the scanning host. | E4: PostgreSQL 8.3.0 - 8.3.7 | F4: TCP/5432 | G4: Nmap; Nuclei | H4: Nuclei: pgsql-empty-password; postgres-default-logins; pgsql-default-db | I4: Not scored | J4: Critical | K4: Nuclei [pgsql-empty-password] critical; [postgres-default-logins] high (postgres/postgres); [pgsql-default-db] high x4 (databases 'postgres' and 'template1', password 'postgres' and empty). | L4: Confirmed by Nuclei credential tests | M4: 5 | N4: {=INDEX('Scoring & Notes'!$B$18:$B$22,MATCH(M4,'Scoring & Notes'!$A$18:$A$22,0))} -> Almost certain | O4: 4 | P4: {=INDEX('Scoring & Notes'!$B$26:$B$30,MATCH(O4,'Scoring & Notes'!$A$26:$A$30,0))} -> Major | Q4: =M4*O4 -> 20 | R4: =IF(Q4>='Scoring & Notes'!$B$34,'Scoring & Notes'!$A$34,IF(Q4>='Scoring & Notes'!$B$35,'Scoring & Notes'!$A$35,IF(Q4>='Scoring & Notes'!$B$36,'Scoring & Notes'!$A$36,'Scoring & Notes'!$A$37))) -> Critical | S4: =IF(OR(R4='Scoring & Notes'!$A$34,R4='Scoring & Notes'!$A$35),"H",IF(R4='Scoring & Notes'!$A$36,"M","L")) -> H | T4: {=INDEX('Scoring & Notes'!$D$34:$D$37,MATCH(R4,'Scoring & Notes'!$A$34:$A$37,0))} -> P1 | U4: Full read/write access to all databases; possible server-side file access and command execution through superuser features; data breach or tampering. | V4: CIS 4.7, 5.2, 6.1 | W4: PR.AA-01; PR.AA-03 | X4: A.5.17; A.8.5 | Y4: Req. 2.2.2, 8.3.1, 8.3.6 | Z4: A07:2021 Identification and Authentication Failures | AA4: Set a strong unique password for 'postgres'; restrict listen_addresses and pg_hba.conf to named application hosts; block TCP/5432 at the host firewall. | AB4: Enforce scram authentication on a supported PostgreSQL release; remove default accounts; vault credentials; log and alert on superuser logins. | AC4: Authentication success was reported by the Nuclei templates. | AD4: Database administrator | AE4: {=INDEX('Scoring & Notes'!$E$34:$E$37,MATCH(R4,'Scoring & Notes'!$A$34:$A$37,0))} -> 7 | AF4: ='Scoring & Notes'!$B$12+AE4 -> 46325 | AG4: Open
A5: R04 | B5: new | C5: Apache JServ (AJP) 'Ghostcat' vulnerability | D5: The AJP connector is reachable and was flagged for Ghostcat: Tomcat trusts AJP connections more than HTTP, so anyone who can reach the port can read files from the web application and process files as JSP, which can lead to remote code execution if uploads are possible. NVD lists Tomcat 7.0.0-7.0.99, 8.5.0-8.5.50 and 9.0.0.M1-9.0.0.30 as affected; Tomcat 5.5 is long unsupported and not in that list, so the template match should be confirmed. | E5: Apache Jserv AJP13 (Tomcat 5.5 on TCP/8180) | F5: TCP/8009 | G5: Nmap; Nuclei | H5: CVE-2020-1938 | I5: 9.8 Critical (CVSS v3.1, NVD) | J5: Critical | K5: Nuclei [CVE-2020-1938] [tcp] [critical] 192.168.164.129:8009. Nmap: 8009/tcp ajp13 Apache Jserv (Protocol v1.3). | L5: Detected by Nuclei template; NVD does not list Tomcat 5.5 - confirm manually | M5: 5 | N5: {=INDEX('Scoring & Notes'!$B$18:$B$22,MATCH(M5,'Scoring & Notes'!$A$18:$A$22,0))} -> Almost certain | O5: 4 | P5: {=INDEX('Scoring & Notes'!$B$26:$B$30,MATCH(O5,'Scoring & Notes'!$A$26:$A$30,0))} -> Major | Q5: =M5*O5 -> 20 | R5: =IF(Q5>='Scoring & Notes'!$B$34,'Scoring & Notes'!$A$34,IF(Q5>='Scoring & Notes'!$B$35,'Scoring & Notes'!$A$35,IF(Q5>='Scoring & Notes'!$B$36,'Scoring & Notes'!$A$36,'Scoring & Notes'!$A$37))) -> Critical | S5: =IF(OR(R5='Scoring & Notes'!$A$34,R5='Scoring & Notes'!$A$35),"H",IF(R5='Scoring & Notes'!$A$36,"M","L")) -> H | T5: {=INDEX('Scoring & Notes'!$D$34:$D$37,MATCH(R5,'Scoring & Notes'!$A$34:$A$37,0))} -> P1 | U5: Disclosure of application source and configuration (including credentials) and possible remote code execution. | V5: CIS 7.1, 7.4, 7.7 | W5: ID.RA-01; PR.PS-02 | X5: A.8.8 | Y5: Req. 6.3.1, 6.3.3 | Z5: A06:2021 Vulnerable and Outdated Components | AA5: Disable the AJP connector or bind it to localhost; block TCP/8009. | AB5: Upgrade Tomcat to a supported, patched release; if AJP is needed, require a shared secret and restrict by address. | AC5: Template-based detection; Nmap ajp-methods returned no valid OPTIONS response and Tomcat 5.5 is outside the NVD affected-version list, so confirm manually. Rating kept Critical because an exposed, unsupported AJP connector is unsafe either way. | AD5: Application owner | AE5: {=INDEX('Scoring & Notes'!$E$34:$E$37,MATCH(R5,'Scoring & Notes'!$A$34:$A$37,0))} -> 7 | AF5: ='Scoring & Notes'!$B$12+AE5 -> 46325 | AG5: Open
A6: R05 | B6: new | C6: distccd remote command execution | D6: distccd, a distributed compiler daemon, accepts jobs from any client unless restricted. A remote user can run arbitrary commands as the daemon account. | E6: distccd v1 (GNU 4.2.4) | F6: TCP/3632 | G6: Nmap; Nuclei | H6: CVE-2004-2687 | I6: 9.3 (CVSS v2, as widely published by NVD; not re-verified) | J6: High | K6: Nuclei [CVE-2004-2687] [tcp] [high] 192.168.164.129:3632. Nmap: 3632/tcp distccd v1. | L6: Detected by Nuclei template (scanner severity High; assessed higher) | M6: 5 | N6: {=INDEX('Scoring & Notes'!$B$18:$B$22,MATCH(M6,'Scoring & Notes'!$A$18:$A$22,0))} -> Almost certain | O6: 4 | P6: {=INDEX('Scoring & Notes'!$B$26:$B$30,MATCH(O6,'Scoring & Notes'!$A$26:$A$30,0))} -> Major | Q6: =M6*O6 -> 20 | R6: =IF(Q6>='Scoring & Notes'!$B$34,'Scoring & Notes'!$A$34,IF(Q6>='Scoring & Notes'!$B$35,'Scoring & Notes'!$A$35,IF(Q6>='Scoring & Notes'!$B$36,'Scoring & Notes'!$A$36,'Scoring & Notes'!$A$37))) -> Critical | S6: =IF(OR(R6='Scoring & Notes'!$A$34,R6='Scoring & Notes'!$A$35),"H",IF(R6='Scoring & Notes'!$A$36,"M","L")) -> H | T6: {=INDEX('Scoring & Notes'!$D$34:$D$37,MATCH(R6,'Scoring & Notes'!$A$34:$A$37,0))} -> P1 | U6: Unauthenticated remote command execution as the daemon user and a stepping stone to privilege escalation. | V6: CIS 4.1, 4.8 | W6: PR.PS-01 | X6: A.8.9 | Y6: Req. 2.2.4 | Z6: A05:2021 Security Misconfiguration | AA6: Stop distccd; block TCP/3632. | AB6: Do not expose compile services; if needed, use --allow with specific hosts, bind to an internal interface and add network ACLs. | AC6: Scanner rated High; assessed Critical because the service design permits remote command execution to any permitted client. | AD6: System administrator | AE6: {=INDEX('Scoring & Notes'!$E$34:$E$37,MATCH(R6,'Scoring & Notes'!$A$34:$A$37,0))} -> 7 | AF6: ='Scoring & Notes'!$B$12+AE6 -> 46325 | AG6: Open
A7: R06 | B7: new | C7: VNC remote desktop with weak password and weak protocol | D7: Remote desktop access is protected only by weak, guessable passwords over the legacy RFB 3.3 protocol, which uses a weak challenge/response and no session encryption. | E7: VNC (RFB 003.003) | F7: TCP/5900 | G7: Nmap; Nuclei | H7: Nuclei: vnc-default-login; vnc-service-detect | I7: Not scored | J7: High | K7: Nuclei [vnc-default-login] high x2 (passwords 'password', 'password123'); [vnc-service-detect] RFB 003.003. Nmap vnc-info: protocol 3.3, security type VNC Authentication (2). | L7: Confirmed by Nuclei credential tests (passwords 'password' and 'password123') | M7: 5 | N7: {=INDEX('Scoring & Notes'!$B$18:$B$22,MATCH(M7,'Scoring & Notes'!$A$18:$A$22,0))} -> Almost certain | O7: 4 | P7: {=INDEX('Scoring & Notes'!$B$26:$B$30,MATCH(O7,'Scoring & Notes'!$A$26:$A$30,0))} -> Major | Q7: =M7*O7 -> 20 | R7: =IF(Q7>='Scoring & Notes'!$B$34,'Scoring & Notes'!$A$34,IF(Q7>='Scoring & Notes'!$B$35,'Scoring & Notes'!$A$35,IF(Q7>='Scoring & Notes'!$B$36,'Scoring & Notes'!$A$36,'Scoring & Notes'!$A$37))) -> Critical | S7: =IF(OR(R7='Scoring & Notes'!$A$34,R7='Scoring & Notes'!$A$35),"H",IF(R7='Scoring & Notes'!$A$36,"M","L")) -> H | T7: {=INDEX('Scoring & Notes'!$D$34:$D$37,MATCH(R7,'Scoring & Notes'!$A$34:$A$37,0))} -> P1 | U7: Interactive desktop control of the host, enabling full compromise, credential capture and tampering. | V7: CIS 4.7, 5.2, 6.1 | W7: PR.AA-01; PR.AA-03 | X7: A.5.17; A.8.5 | Y7: Req. 2.2.2, 8.3.1, 8.3.6 | Z7: A07:2021 Identification and Authentication Failures | AA7: Change the VNC password or stop the service; block TCP/5900 except via an SSH tunnel or VPN. | AB7: Replace with an encrypted, MFA-protected remote access method; enforce password policy; monitor remote access. | AC7: Credential success reported by Nuclei. | AD7: System administrator | AE7: {=INDEX('Scoring & Notes'!$E$34:$E$37,MATCH(R7,'Scoring & Notes'!$A$34:$A$37,0))} -> 7 | AF7: ='Scoring & Notes'!$B$12+AE7 -> 46325 | AG7: Open
A8: R07 | B8: new | C8: UnrealIRCd 3.2.8.1 (release known to have been trojaned) | D8: Source tarballs of UnrealIRCd 3.2.8.1 distributed in 2009-2010 contained a backdoor allowing remote command execution. A version string alone does not show whether this host runs the trojaned build. | E8: UnrealIRCd 3.2.8.1 | F8: TCP/6667, 6697 | G8: Nmap | H8: CVE-2010-2075 (applicability to validate) | I8: Not scored here | J8: n/a (not flagged) | K8: Nmap irc-info on both ports: version 'Unreal3.2.8.1. irc.Metasploitable.LAN'. | L8: Version indicator only; validate | M8: 3 | N8: {=INDEX('Scoring & Notes'!$B$18:$B$22,MATCH(M8,'Scoring & Notes'!$A$18:$A$22,0))} -> Possible | O8: 5 | P8: {=INDEX('Scoring & Notes'!$B$26:$B$30,MATCH(O8,'Scoring & Notes'!$A$26:$A$30,0))} -> Severe | Q8: =M8*O8 -> 15 | R8: =IF(Q8>='Scoring & Notes'!$B$34,'Scoring & Notes'!$A$34,IF(Q8>='Scoring & Notes'!$B$35,'Scoring & Notes'!$A$35,IF(Q8>='Scoring & Notes'!$B$36,'Scoring & Notes'!$A$36,'Scoring & Notes'!$A$37))) -> High | S8: =IF(OR(R8='Scoring & Notes'!$A$34,R8='Scoring & Notes'!$A$35),"H",IF(R8='Scoring & Notes'!$A$36,"M","L")) -> H | T8: {=INDEX('Scoring & Notes'!$D$34:$D$37,MATCH(R8,'Scoring & Notes'!$A$34:$A$37,0))} -> P2 | U8: If trojaned: unauthenticated remote command execution. Otherwise: an unnecessary, outdated chat service. | V8: CIS 7.1, 7.4, 7.7 | W8: ID.RA-01; PR.PS-02 | X8: A.8.8 | Y8: Req. 6.3.1, 6.3.3 | Z8: A06:2021 Vulnerable and Outdated Components | AA8: Stop the IRC services; block TCP/6667 and 6697. | AB8: Remove IRC from the server; if required, install a supported release from a verified source and compare checksums. | AC8: Do not report as confirmed backdoor without validation (package/source checksum). | AD8: System administrator | AE8: {=INDEX('Scoring & Notes'!$E$34:$E$37,MATCH(R8,'Scoring & Notes'!$A$34:$A$37,0))} -> 30 | AF8: ='Scoring & Notes'!$B$12+AE8 -> 46348 | AG8: Open
A9: R08 | B9: R03 | C9: Telnet service exposed (cleartext remote login) | D9: Telnet transmits usernames, passwords and session data in plaintext and is obsolete for administration. | E9: Linux telnetd | F9: TCP/23 | G9: Nmap | H9: No CVE (insecure protocol) | I9: Not scored | J9: n/a | K9: Nmap: '23/tcp open telnet Linux telnetd'. | L9: Observed (Nmap -sV) | M9: 4 | N9: {=INDEX('Scoring & Notes'!$B$18:$B$22,MATCH(M9,'Scoring & Notes'!$A$18:$A$22,0))} -> Likely | O9: 4 | P9: {=INDEX('Scoring & Notes'!$B$26:$B$30,MATCH(O9,'Scoring & Notes'!$A$26:$A$30,0))} -> Major | Q9: =M9*O9 -> 16 | R9: =IF(Q9>='Scoring & Notes'!$B$34,'Scoring & Notes'!$A$34,IF(Q9>='Scoring & Notes'!$B$35,'Scoring & Notes'!$A$35,IF(Q9>='Scoring & Notes'!$B$36,'Scoring & Notes'!$A$36,'Scoring & Notes'!$A$37))) -> High | S9: =IF(OR(R9='Scoring & Notes'!$A$34,R9='Scoring & Notes'!$A$35),"H",IF(R9='Scoring & Notes'!$A$36,"M","L")) -> H | T9: {=INDEX('Scoring & Notes'!$D$34:$D$37,MATCH(R9,'Scoring & Notes'!$A$34:$A$37,0))} -> P2 | U9: Credential and session interception on any shared network path, leading to unauthorised access. | V9: CIS 3.10, 12.6 | W9: PR.DS-02 | X9: A.8.24; A.5.14 | Y9: Req. 2.2.7, 4.2.1 | Z9: A02:2021 Cryptographic Failures | AA9: Disable telnetd; block TCP/23. | AB9: Use SSH with key-based authentication for administration; apply the baseline that prohibits cleartext management protocols. | AC9: Risk depends on network path and authentication configuration. | AD9: System administrator | AE9: {=INDEX('Scoring & Notes'!$E$34:$E$37,MATCH(R9,'Scoring & Notes'!$A$34:$A$37,0))} -> 30 | AF9: ='Scoring & Notes'!$B$12+AE9 -> 46348 | AG9: Open
A10: R09 | B10: new | C10: Legacy r-services exposed (rexec, rlogin, rsh) | D10: The r-services use cleartext transport and host-based trust (.rhosts) rather than strong authentication. | E10: netkit-rsh rexecd; login; Netkit rshd | F10: TCP/512, 513, 514 | G10: Nmap | H10: No CVE (insecure protocols) | I10: Not scored | J10: n/a | K10: Nmap: 512/tcp exec netkit-rsh rexecd; 513/tcp login?; 514/tcp shell Netkit rshd. | L10: Observed (Nmap -sV) | M10: 4 | N10: {=INDEX('Scoring & Notes'!$B$18:$B$22,MATCH(M10,'Scoring & Notes'!$A$18:$A$22,0))} -> Likely | O10: 4 | P10: {=INDEX('Scoring & Notes'!$B$26:$B$30,MATCH(O10,'Scoring & Notes'!$A$26:$A$30,0))} -> Major | Q10: =M10*O10 -> 16 | R10: =IF(Q10>='Scoring & Notes'!$B$34,'Scoring & Notes'!$A$34,IF(Q10>='Scoring & Notes'!$B$35,'Scoring & Notes'!$A$35,IF(Q10>='Scoring & Notes'!$B$36,'Scoring & Notes'!$A$36,'Scoring & Notes'!$A$37))) -> High | S10: =IF(OR(R10='Scoring & Notes'!$A$34,R10='Scoring & Notes'!$A$35),"H",IF(R10='Scoring & Notes'!$A$36,"M","L")) -> H | T10: {=INDEX('Scoring & Notes'!$D$34:$D$37,MATCH(R10,'Scoring & Notes'!$A$34:$A$37,0))} -> P2 | U10: Unauthorised command execution or login through trusted-host abuse and credential interception. | V10: CIS 3.10, 12.6 | W10: PR.DS-02 | X10: A.8.24; A.5.14 | Y10: Req. 2.2.7, 4.2.1 | Z10: A02:2021 Cryptographic Failures | AA10: Disable rexecd, rlogind and rshd; block TCP/512-514. | AB10: Remove the rsh server packages; use SSH only. | AC10: Trust configuration (.rhosts, hosts.equiv) not reviewed. | AD10: System administrator | AE10: {=INDEX('Scoring & Notes'!$E$34:$E$37,MATCH(R10,'Scoring & Notes'!$A$34:$A$37,0))} -> 30 | AF10: ='Scoring & Notes'!$B$12+AE10 -> 46348 | AG10: Open
A11: R10 | B11: R02 | C11: Anonymous FTP login and weak FTP credentials | D11: The FTP service accepts anonymous login. The eight 'weak credential' hits all use the account 'ftp', which is the anonymous account; they most likely reflect anonymous access accepting any password rather than eight separate weak passwords. FTP also sends data in cleartext. | E11: FTP - vsftpd 2.3.4 | F11: TCP/21 | G11: Nmap; Nuclei | H11: Nmap ftp-anon; Nuclei ftp-anonymous-login; ftp-weak-credentials | I11: Not scored | J11: High (weak credentials); Medium (anonymous) | K11: Nmap ftp-anon: 'Anonymous FTP login allowed (FTP code 230)'; ftp-syst: control and data connections are plain text. Nuclei [ftp-anonymous-login] medium; [ftp-weak-credentials] high x8 for user 'ftp' (passwords password, default, nas, 123456, guest, stingray, pass1, toor). | L11: Confirmed (Nmap script and Nuclei) | M11: 5 | N11: {=INDEX('Scoring & Notes'!$B$18:$B$22,MATCH(M11,'Scoring & Notes'!$A$18:$A$22,0))} -> Almost certain | O11: 3 | P11: {=INDEX('Scoring & Notes'!$B$26:$B$30,MATCH(O11,'Scoring & Notes'!$A$26:$A$30,0))} -> Moderate | Q11: =M11*O11 -> 15 | R11: =IF(Q11>='Scoring & Notes'!$B$34,'Scoring & Notes'!$A$34,IF(Q11>='Scoring & Notes'!$B$35,'Scoring & Notes'!$A$35,IF(Q11>='Scoring & Notes'!$B$36,'Scoring & Notes'!$A$36,'Scoring & Notes'!$A$37))) -> High | S11: =IF(OR(R11='Scoring & Notes'!$A$34,R11='Scoring & Notes'!$A$35),"H",IF(R11='Scoring & Notes'!$A$36,"M","L")) -> H | T11: {=INDEX('Scoring & Notes'!$D$34:$D$37,MATCH(R11,'Scoring & Notes'!$A$34:$A$37,0))} -> P2 | U11: Unauthorised file access or upload, service abuse, and interception of any credentials or data sent over FTP. | V11: CIS 4.7, 5.2, 6.1 | W11: PR.AA-01; PR.AA-03 | X11: A.5.17; A.8.5 | Y11: Req. 2.2.2, 8.3.1, 8.3.6 | Z11: A07:2021 Identification and Authentication Failures | AA11: Disable anonymous access unless formally approved; restrict directories and source addresses. | AB11: Replace FTP with SFTP or FTPS; apply least-privilege chroot; review the upload directory. | AC11: Interpretation of the eight weak-credential hits as an anonymous-account artefact is an analyst inference. | AD11: System administrator | AE11: {=INDEX('Scoring & Notes'!$E$34:$E$37,MATCH(R11,'Scoring & Notes'!$A$34:$A$37,0))} -> 30 | AF11: ='Scoring & Notes'!$B$12+AE11 -> 46348 | AG11: Open
A12: R11 | B12: R08 (part) | C12: Samba 3.0.20 flagged for CVE-2026-4480 (version-based) | D12: CVE-2026-4480 is an OS command injection in Samba's printing subsystem (the 'print command' %J substitution is not escaped). The Nuclei match is based on the version string. Exploitation depends on the print command configuration and has high attack complexity, so the scanner's Critical label is reduced to High pending validation. | E12: Samba smbd 3.0.20-Debian | F12: TCP/445 | G12: Nmap; Nuclei | H12: CVE-2026-4480 | I12: 9.0 Critical (CVSS v3.1, AC:H) | J12: Critical | K12: Nuclei [CVE-2026-4480:version] [javascript] [critical] 192.168.164.129:445 ['3.0.20']; [samba-detect] 'Samba 3.0.20-Debian'. Nmap: smbd 3.0.20-Debian. | L12: Version-based match by Nuclei; applicability to validate | M12: 3 | N12: {=INDEX('Scoring & Notes'!$B$18:$B$22,MATCH(M12,'Scoring & Notes'!$A$18:$A$22,0))} -> Possible | O12: 5 | P12: {=INDEX('Scoring & Notes'!$B$26:$B$30,MATCH(O12,'Scoring & Notes'!$A$26:$A$30,0))} -> Severe | Q12: =M12*O12 -> 15 | R12: =IF(Q12>='Scoring & Notes'!$B$34,'Scoring & Notes'!$A$34,IF(Q12>='Scoring & Notes'!$B$35,'Scoring & Notes'!$A$35,IF(Q12>='Scoring & Notes'!$B$36,'Scoring & Notes'!$A$36,'Scoring & Notes'!$A$37))) -> High | S12: =IF(OR(R12='Scoring & Notes'!$A$34,R12='Scoring & Notes'!$A$35),"H",IF(R12='Scoring & Notes'!$A$36,"M","L")) -> H | T12: {=INDEX('Scoring & Notes'!$D$34:$D$37,MATCH(R12,'Scoring & Notes'!$A$34:$A$37,0))} -> P2 | U12: Potential remote code execution on the file server. | V12: CIS 7.1, 7.4, 7.7 | W12: ID.RA-01; PR.PS-02 | X12: A.8.8 | Y12: Req. 6.3.1, 6.3.3 | Z12: A06:2021 Vulnerable and Outdated Components | AA12: Restrict TCP/139 and 445 to approved clients; review smb.conf for 'print command' and printing shares. | AB12: Upgrade Samba to a supported, patched release; disable printing support if not needed. | AC12: Public advisories show inconsistent fixed-version data; confirm against the upstream Samba security advisory and the installed build. | AD12: System administrator | AE12: {=INDEX('Scoring & Notes'!$E$34:$E$37,MATCH(R12,'Scoring & Notes'!$A$34:$A$37,0))} -> 30 | AF12: ='Scoring & Notes'!$B$12+AE12 -> 46348 | AG12: Open
A13: R12 | B13: R08 (part) | C13: SMB weaknesses: SMBv1, guest access and signing disabled | D13: The host speaks only legacy SMB 1.0, allows guest sessions and does not require message signing, which enables relay and tampering attacks. | E13: Samba smbd 3.0.20-Debian | F13: TCP/139, 445 (UDP/137) | G13: Nmap; Nuclei | H13: Nmap smb-security-mode; Nuclei smb-v1-supported | I13: Not scored | J13: Info | K13: Nmap smb-security-mode: account_used guest; message_signing disabled (dangerous, but default); smb2-time: protocol negotiation failed (SMB2). Nuclei [smb-v1-supported] and [smb-version-detect] 'SMB 1.0'; [ntlm-info] 'Samba 3.0.20-Debian'. | L13: Observed (Nmap and Nuclei) | M13: 4 | N13: {=INDEX('Scoring & Notes'!$B$18:$B$22,MATCH(M13,'Scoring & Notes'!$A$18:$A$22,0))} -> Likely | O13: 3 | P13: {=INDEX('Scoring & Notes'!$B$26:$B$30,MATCH(O13,'Scoring & Notes'!$A$26:$A$30,0))} -> Moderate | Q13: =M13*O13 -> 12 | R13: =IF(Q13>='Scoring & Notes'!$B$34,'Scoring & Notes'!$A$34,IF(Q13>='Scoring & Notes'!$B$35,'Scoring & Notes'!$A$35,IF(Q13>='Scoring & Notes'!$B$36,'Scoring & Notes'!$A$36,'Scoring & Notes'!$A$37))) -> High | S13: =IF(OR(R13='Scoring & Notes'!$A$34,R13='Scoring & Notes'!$A$35),"H",IF(R13='Scoring & Notes'!$A$36,"M","L")) -> H | T13: {=INDEX('Scoring & Notes'!$D$34:$D$37,MATCH(R13,'Scoring & Notes'!$A$34:$A$37,0))} -> P2 | U13: Unauthorised share access, information disclosure and man-in-the-middle manipulation of SMB traffic. | V13: CIS 3.3, 6.1, 6.8 | W13: PR.AA-05 | X13: A.5.15; A.8.3 | Y13: Req. 7.2 | Z13: A01:2021 Broken Access Control | AA13: Disable guest access; require SMB signing; restrict to approved hosts. | AB13: Disable SMB1; move to a supported Samba/SMB 3 configuration with encryption. | AC13: Share-level permissions were not enumerated. | AD13: System administrator | AE13: {=INDEX('Scoring & Notes'!$E$34:$E$37,MATCH(R13,'Scoring & Notes'!$A$34:$A$37,0))} -> 30 | AF13: ='Scoring & Notes'!$B$12+AE13 -> 46348 | AG13: Open
... A39: R38 | B39: new | C39: NetBIOS and RPC information disclosure | D39: Name services disclose host name, domain and OS details that assist reconnaissance. | E39: NetBIOS name service; RPC portmapper | F39: UDP/137, UDP/111 | G39: Nmap; Nuclei | H39: Nuclei netbios-udp-detect, rpc-udp-detect; Nmap nbstat, smb-os-discovery | I39: Not scored | J39: Info | K39: Nuclei [netbios-udp-detect] on UDP/137; [rpc-udp-detect] on UDP/111. Nmap nbstat: NetBIOS name METASPLOITABLE; smb-os-discovery: OS Unix (Samba 3.0.20-Debian), computer name metasploitable, domain localdomain, FQDN metasploitable.localdomain. | L39: Observed (Nmap and Nuclei) | M39: 3 | N39: {=INDEX('Scoring & Notes'!$B$18:$B$22,MATCH(M39,'Scoring & Notes'!$A$18:$A$22,0))} -> Possible | O39: 2 | P39: {=INDEX('Scoring & Notes'!$B$26:$B$30,MATCH(O39,'Scoring & Notes'!$A$26:$A$30,0))} -> Minor | Q39: =M39*O39 -> 6 | R39: =IF(Q39>='Scoring & Notes'!$B$34,'Scoring & Notes'!$A$34,IF(Q39>='Scoring & Notes'!$B$35,'Scoring & Notes'!$A$35,IF(Q39>='Scoring & Notes'!$B$36,'Scoring & Notes'!$A$36,'Scoring & Notes'!$A$37))) -> Low | S39: =IF(OR(R39='Scoring & Notes'!$A$34,R39='Scoring & Notes'!$A$35),"H",IF(R39='Scoring & Notes'!$A$36,"M","L")) -> L | T39: {=INDEX('Scoring & Notes'!$D$34:$D$37,MATCH(R39,'Scoring & Notes'!$A$34:$A$37,0))} -> P4 | U39: Reconnaissance support. | V39: CIS 16.7, 4.1 | W39: PR.PS-01 | X39: A.8.9 | Y39: Req. 6.2.4 | Z39: A05:2021 Security Misconfiguration (CWE-200) | AA39: Block UDP/137 and 111 from untrusted hosts. | AB39: Disable NetBIOS over TCP/IP where not needed. | AC39: Observed. | AD39: Network/security engineer | AE39: {=INDEX('Scoring & Notes'!$E$34:$E$37,MATCH(R39,'Scoring & Notes'!$A$34:$A$37,0))} -> 180 | AF39: ='Scoring & Notes'!$B$12+AE39 -> 46498 | AG39: Open

Sheet Heat Map
A1: Risk Heat Map (count of findings per Likelihood x Impact cell)
A2: Live COUNTIFS over the Risk Register. Cell colour shows the rating zone from the thresholds on 'Scoring & Notes'.
C4: LIKELIHOOD
A5: IMPACT | B5: Score | C5: {=1&" - "&INDEX('Scoring & Notes'!$B$18:$B$22,1)} -> 1 - Rare | D5: {=2&" - "&INDEX('Scoring & Notes'!$B$18:$B$22,2)} -> 2 - Unlikely | E5: {=3&" - "&INDEX('Scoring & Notes'!$B$18:$B$22,3)} -> 3 - Possible | F5: {=4&" - "&INDEX('Scoring & Notes'!$B$18:$B$22,4)} -> 4 - Likely | G5: {=5&" - "&INDEX('Scoring & Notes'!$B$18:$B$22,5)} -> 5 - Almost certain
A6: {=5&" - "&INDEX('Scoring & Notes'!$B$26:$B$30,5)} -> 5 - Severe | B6: 5 | C6: =COUNTIFS('Risk Register'!$M$2:$M$39,1,'Risk Register'!$O$2:$O$39,$B6) -> 0 | D6: =COUNTIFS('Risk Register'!$M$2:$M$39,2,'Risk Register'!$O$2:$O$39,$B6) -> 0 | E6: =COUNTIFS('Risk Register'!$M$2:$M$39,3,'Risk Register'!$O$2:$O$39,$B6) -> 2 | F6: =COUNTIFS('Risk Register'!$M$2:$M$39,4,'Risk Register'!$O$2:$O$39,$B6) -> 0 | G6: =COUNTIFS('Risk Register'!$M$2:$M$39,5,'Risk Register'!$O$2:$O$39,$B6) -> 2
A7: {=4&" - "&INDEX('Scoring & Notes'!$B$26:$B$30,4)} -> 4 - Major | B7: 4 | C7: =COUNTIFS('Risk Register'!$M$2:$M$39,1,'Risk Register'!$O$2:$O$39,$B7) -> 0 | D7: =COUNTIFS('Risk Register'!$M$2:$M$39,2,'Risk Register'!$O$2:$O$39,$B7) -> 1 | E7: =COUNTIFS('Risk Register'!$M$2:$M$39,3,'Risk Register'!$O$2:$O$39,$B7) -> 1 | F7: =COUNTIFS('Risk Register'!$M$2:$M$39,4,'Risk Register'!$O$2:$O$39,$B7) -> 8 | G7: =COUNTIFS('Risk Register'!$M$2:$M$39,5,'Risk Register'!$O$2:$O$39,$B7) -> 4
A8: {=3&" - "&INDEX('Scoring & Notes'!$B$26:$B$30,3)} -> 3 - Moderate | B8: 3 | C8: =COUNTIFS('Risk Register'!$M$2:$M$39,1,'Risk Register'!$O$2:$O$39,$B8) -> 0 | D8: =COUNTIFS('Risk Register'!$M$2:$M$39,2,'Risk Register'!$O$2:$O$39,$B8) -> 1 | E8: =COUNTIFS('Risk Register'!$M$2:$M$39,3,'Risk Register'!$O$2:$O$39,$B8) -> 7 | F8: =COUNTIFS('Risk Register'!$M$2:$M$39,4,'Risk Register'!$O$2:$O$39,$B8) -> 1 | G8: =COUNTIFS('Risk Register'!$M$2:$M$39,5,'Risk Register'!$O$2:$O$39,$B8) -> 2
A9: {=2&" - "&INDEX('Scoring & Notes'!$B$26:$B$30,2)} -> 2 - Minor | B9: 2 | C9: =COUNTIFS('Risk Register'!$M$2:$M$39,1,'Risk Register'!$O$2:$O$39,$B9) -> 0 | D9: =COUNTIFS('Risk Register'!$M$2:$M$39,2,'Risk Register'!$O$2:$O$39,$B9) -> 1 | E9: =COUNTIFS('Risk Register'!$M$2:$M$39,3,'Risk Register'!$O$2:$O$39,$B9) -> 6 | F9: =COUNTIFS('Risk Register'!$M$2:$M$39,4,'Risk Register'!$O$2:$O$39,$B9) -> 2 | G9: =COUNTIFS('Risk Register'!$M$2:$M$39,5,'Risk Register'!$O$2:$O$39,$B9) -> 0
A10: {=1&" - "&INDEX('Scoring & Notes'!$B$26:$B$30,1)} -> 1 - Insignificant | B10: 1 | C10: =COUNTIFS('Risk Register'!$M$2:$M$39,1,'Risk Register'!$O$2:$O$39,$B10) -> 0 | D10: =COUNTIFS('Risk Register'!$M$2:$M$39,2,'Risk Register'!$O$2:$O$39,$B10) -> 0 | E10: =COUNTIFS('Risk Register'!$M$2:$M$39,3,'Risk Register'!$O$2:$O$39,$B10) -> 0 | F10: =COUNTIFS('Risk Register'!$M$2:$M$39,4,'Risk Register'!$O$2:$O$39,$B10) -> 0 | G10: =COUNTIFS('Risk Register'!$M$2:$M$39,5,'Risk Register'!$O$2:$O$39,$B10) -> 0
A12: Colour key (default thresholds):
A13: Critical | C13: High | D13: Medium | E13: Low
A14: Check: total | C14: =SUM(C6:G10) -> 38
A16: Note: zone colours are fixed to the default thresholds; if the thresholds on 'Scoring & Notes' are changed, the counts stay correct but the zone shading should be reviewed.

Sheet Open Ports
A1: Open TCP Port Inventory (Nmap -sV -sC -O -p-)
A2: Scan started Thu 22 Oct 2026 04:57:27 EDT; completed 05:00:32 (184.73 s). Host up, latency 0.0011 s, MAC 00:0C:29:5B:0B:68 (VMware). OS match Linux 2.6.9 - 2.6.33 (100%).
A4: Port | B4: Proto | C4: State | D4: Service | E4: Product / version | F4: Key script output / note | G4: Related findings
A5: 21 | B5: tcp | C5: open | D5: ftp | E5: vsftpd 2.3.4 | F5: Anonymous login allowed (230); cleartext control/data | G5: R01, R10
A6: 22 | B6: tcp | C6: open | D6: ssh | E6: OpenSSH 4.7p1 Debian 8ubuntu1 (protocol 2.0) | F6: Host keys: 1024-bit DSA, 2048-bit RSA | G6: R26
A7: 23 | B7: tcp | C7: open | D7: telnet | E7: Linux telnetd | F7: Cleartext remote login | G7: R08
A8: 25 | B8: tcp | C8: open | D8: smtp | E8: Postfix smtpd | F8: SSLv2 supported; VRFY/ETRN; certificate expired 2010-04-16 | G8: R18, R31, R32
A9: 53 | B9: tcp | C9: open | D9: domain | E9: ISC BIND 9.4.2 | F9: bind.version 9.4.2 | G9: R27
A10: 80 | B10: tcp | C10: open | D10: http | E10: Apache httpd 2.2.8 ((Ubuntu) DAV/2) | F10: Title: Metasploitable2 - Linux; PHP 5.2.4 | G10: R13, R14, R22-R25, R33-R35
A11: 111 | B11: tcp | C11: open | D11: rpcbind | E11: RPC #100000 v2 | F11: rpcinfo lists nfs, mountd, nlockmgr, status | G11: R21, R38
A12: 139 | B12: tcp | C12: open | D12: netbios-ssn | E12: Samba smbd 3.X - 4.X (WORKGROUP) | F12: SMB over NetBIOS | G12: R12
A13: 445 | B13: tcp | C13: open | D13: netbios-ssn | E13: Samba smbd 3.0.20-Debian (WORKGROUP) | F13: Guest account; message signing disabled; SMBv1 | G13: R11, R12
A14: 512 | B14: tcp | C14: open | D14: exec | E14: netkit-rsh rexecd | F14: r-service | G14: R09
A15: 513 | B15: tcp | C15: open | D15: login? | E15: (unidentified) | F15: r-service (rlogin) | G15: R09
A16: 514 | B16: tcp | C16: open | D16: shell | E16: Netkit rshd | F16: r-service | G16: R09
... A34: 59365 | B34: tcp | C34: open | D34: java-rmi | E34: GNU Classpath grmiregistry | F34: RMI registry | G34: R29
D36: Open ports | E36: =COUNTA(A5:A34) -> 30
D37: Source: Nmap output (initial_scan.nmap/.xml) and HTML report screenshots; 65,505 further ports were closed (reset), none filtered.

Sheet Nuclei Results
A1: Nuclei Scan Results (59 results)
A2: Nuclei v3.11.1 with nuclei-templates cloned manually after the update timeout. Each result is mapped to a Risk Register finding.
A4: # | B4: Template ID | C4: Protocol | D4: Severity | E4: Target (host:port / URL) | F4: Matcher / detail | G4: Mapped finding | H4: Mapped finding title | I4: Raw output line
A5: 1 | B5: CVE-2012-1823 | C5: http | D5: High | E5: 192.168.164.129/index.php?-d+allow_url_include%3don+-d+auto_prepend_file%3dphp%3a//input | G5: R13 | H5: {=INDEX('Risk Register'!$C$2:$C$39,MATCH(G5,'Risk Register'!$A$2:$A$39,0))} -> PHP-CGI argument injection | I5: [CVE-2012-1823] [http] [high] http://192.168.164.129/index.php?-d+allow_url_include%3don+-d+auto_prepend_file%3dphp%3a//input
A6: 2 | B6: phpmyadmin-panel | C6: http | D6: Info | E6: 192.168.164.129/phpMyAdmin/ | F6: [paths="/phpMyAdmin/"] | G6: R22 | H6: {=INDEX('Risk Register'!$C$2:$C$39,MATCH(G6,'Risk Register'!$A$2:$A$39,0))} -> phpMyAdmin administration interface exposed | I6: [phpmyadmin-panel] [http] [info] http://192.168.164.129/phpMyAdmin/ [paths="/phpMyAdmin/"]
A7: 3 | B7: phpinfo-files | C7: http | D7: Low | E7: 192.168.164.129/phpinfo.php | F7: [paths="/phpinfo.php"] | G7: R23 | H7: {=INDEX('Risk Register'!$C$2:$C$39,MATCH(G7,'Risk Register'!$A$2:$A$39,0))} -> phpinfo() test script exposed | I7: [phpinfo-files] [http] [low] http://192.168.164.129/phpinfo.php [paths="/phpinfo.php"]
A8: 4 | B8: http-trace:trace-request | C8: http | D8: Info | E8: 192.168.164.129 | G8: R33 | H8: {=INDEX('Risk Register'!$C$2:$C$39,MATCH(G8,'Risk Register'!$A$2:$A$39,0))} -> HTTP TRACE method enabled | I8: [http-trace:trace-request] [http] [info] http://192.168.164.129
A9: 5 | B9: apache-mod-negotiation-listing:exposed_files | C9: http | D9: Low | E9: 192.168.164.129/index | F9: ["index.php"] [path="/index"] | G9: R35 | H9: {=INDEX('Risk Register'!$C$2:$C$39,MATCH(G9,'Risk Register'!$A$2:$A$39,0))} -> Information leakage through headers, ETag and error behaviour | I9: [apache-mod-negotiation-listing:exposed_files] [http] [low] http://192.168.164.129/index ["index.php"] [path="/index"]
A10: 6 | B10: php-detect | C10: http | D10: Info | E10: 192.168.164.129 | F10: ["5.2.4"] | G10: R14 | H10: {=INDEX('Risk Register'!$C$2:$C$39,MATCH(G10,'Risk Register'!$A$2:$A$39,0))} -> End-of-life web stack: Apache 2.2.8 and PHP 5.2.4 | I10: [php-detect] [http] [info] http://192.168.164.129 ["5.2.4"]
A11: 7 | B11: waf-detect:apachegeneric | C11: http | D11: Info | E11: 192.168.164.129 | G11: R35 | H11: {=INDEX('Risk Register'!$C$2:$C$39,MATCH(G11,'Risk Register'!$A$2:$A$39,0))} -> Information leakage through headers, ETag and error behaviour | I11: [waf-detect:apachegeneric] [http] [info] http://192.168.164.129
A12: 8 | B12: CVE-2026-4480:version | C12: javascript | D12: Critical | E12: 192.168.164.129:445 | F12: ["3.0.20"] | G12: R11 | H12: {=INDEX('Risk Register'!$C$2:$C$39,MATCH(G12,'Risk Register'!$A$2:$A$39,0))} -> Samba 3.0.20 flagged for CVE-2026-4480 (version-based) | I12: [CVE-2026-4480:version] [javascript] [critical] 192.168.164.129:445 ["3.0.20"]
A13: 9 | B13: postgres-default-logins | C13: javascript | D13: High | E13: 192.168.164.129:5432 | F13: passwords='postgres', usernames='postgres' | G13: R03 | H13: {=INDEX('Risk Register'!$C$2:$C$39,MATCH(G13,'Risk Register'!$A$2:$A$39,0))} -> PostgreSQL accessible with empty and default credentials | I13: [postgres-default-logins] [javascript] [high] 192.168.164.129:5432 [FQDN="192.168.164.129",Host="192.168.164.129",Hostname="192.168.164.129:5432",Port="5432",passwords="postgres",usernames="postgres"]
A14: 10 | B14: vnc-default-login | C14: javascript | D14: High | E14: 192.168.164.129:5900 | F14: passwords='password' | G14: R06 | H14: {=INDEX('Risk Register'!$C$2:$C$39,MATCH(G14,'Risk Register'!$A$2:$A$39,0))} -> VNC remote desktop with weak password and weak protocol | I14: [vnc-default-login] [javascript] [high] 192.168.164.129:5900 [FQDN="192.168.164.129",Host="192.168.164.129",Hostname="192.168.164.129:5900",Port="5900",passwords="password"]
A15: 11 | B15: vnc-default-login | C15: javascript | D15: High | E15: 192.168.164.129:5900 | F15: passwords='password123' | G15: R06 | H15: {=INDEX('Risk Register'!$C$2:$C$39,MATCH(G15,'Risk Register'!$A$2:$A$39,0))} -> VNC remote desktop with weak password and weak protocol | I15: [vnc-default-login] [javascript] [high] 192.168.164.129:5900 [FQDN="192.168.164.129",Host="192.168.164.129",Hostname="192.168.164.129:5900",Port="5900",passwords="password123"]
A16: 12 | B16: samba-detect | C16: javascript | D16: Info | E16: 192.168.164.129:445 | F16: ["Samba 3.0.20-Debian"] | G16: R11 | H16: {=INDEX('Risk Register'!$C$2:$C$39,MATCH(G16,'Risk Register'!$A$2:$A$39,0))} -> Samba 3.0.20 flagged for CVE-2026-4480 (version-based) | I16: [samba-detect] [javascript] [info] 192.168.164.129:445 ["Samba 3.0.20-Debian"]
A17: 13 | B17: pgsql-default-db | C17: javascript | D17: High | E17: 192.168.164.129:5432 | F17: database='postgres', password='postgres', usernames='postgres' | G17: R03 | H17: {=INDEX('Risk Register'!$C$2:$C$39,MATCH(G17,'Risk Register'!$A$2:$A$39,0))} -> PostgreSQL accessible with empty and default credentials | I17: [pgsql-default-db] [javascript] [high] 192.168.164.129:5432 [FQDN="192.168.164.129",Host="192.168.164.129",Hostname="192.168.164.129:5432",Port="5432",database="postgres",password="postgres",usernames="postgres"]
A18: 14 | B18: pgsql-default-db | C18: javascript | D18: High | E18: 192.168.164.129:5432 | F18: database='postgres', password='', usernames='postgres' | G18: R03 | H18: {=INDEX('Risk Register'!$C$2:$C$39,MATCH(G18,'Risk Register'!$A$2:$A$39,0))} -> PostgreSQL accessible with empty and default credentials | I18: [pgsql-default-db] [javascript] [high] 192.168.164.129:5432 [FQDN="192.168.164.129",Host="192.168.164.129",Hostname="192.168.164.129:5432",Port="5432",database="postgres",password="",usernames="postgres"]
A19: 15 | B19: pgsql-default-db | C19: javascript | D19: High | E19: 192.168.164.129:5432 | F19: database='template1', password='postgres', usernames='postgres' | G19: R03 | H19: {=INDEX('Risk Register'!$C$2:$C$39,MATCH(G19,'Risk Register'!$A$2:$A$39,0))} -> PostgreSQL accessible with empty and default credentials | I19: [pgsql-default-db] [javascript] [high] 192.168.164.129:5432 [FQDN="192.168.164.129",Host="192.168.164.129",Hostname="192.168.164.129:5432",Port="5432",database="template1",password="postgres",usernames="postgres"]
A20: 16 | B20: pgsql-default-db | C20: javascript | D20: High | E20: 192.168.164.129:5432 | F20: database='template1', password='', usernames='postgres' | G20: R03 | H20: {=INDEX('Risk Register'!$C$2:$C$39,MATCH(G20,'Risk Register'!$A$2:$A$39,0))} -> PostgreSQL accessible with empty and default credentials | I20: [pgsql-default-db] [javascript] [high] 192.168.164.129:5432 [FQDN="192.168.164.129",Host="192.168.164.129",Hostname="192.168.164.129:5432",Port="5432",database="template1",password="",usernames="postgres"]
A21: 17 | B21: ntlm-info | C21: javascript | D21: Info | E21: 192.168.164.129:445 | F21: ["NTLM: Samba 3.0.20-Debian"] | G21: R12 | H21: {=INDEX('Risk Register'!$C$2:$C$39,MATCH(G21,'Risk Register'!$A$2:$A$39,0))} -> SMB weaknesses: SMBv1, guest access and signing disabled | I21: [ntlm-info] [javascript] [info] 192.168.164.129:445 ["NTLM: Samba 3.0.20-Debian"]
A22: 18 | B22: smb-v1-supported | C22: javascript | D22: Info | E22: 192.168.164.129:445 | G22: R12 | H22: {=INDEX('Risk Register'!$C$2:$C$39,MATCH(G22,'Risk Register'!$A$2:$A$39,0))} -> SMB weaknesses: SMBv1, guest access and signing disabled | I22: [smb-v1-supported] [javascript] [info] 192.168.164.129:445
A23: 19 | B23: smb-version-detect:smb-version | C23: javascript | D23: Info | E23: 192.168.164.129:445 | F23: ["SMB 1.0"] | G23: R12 | H23: {=INDEX('Risk Register'!$C$2:$C$39,MATCH(G23,'Risk Register'!$A$2:$A$39,0))} -> SMB weaknesses: SMBv1, guest access and signing disabled | I23: [smb-version-detect:smb-version] [javascript] [info] 192.168.164.129:445 ["SMB 1.0"]
A24: 20 | B24: pgsql-empty-password | C24: javascript | D24: Critical | E24: 192.168.164.129:5432 | G24: R03 | H24: {=INDEX('Risk Register'!$C$2:$C$39,MATCH(G24,'Risk Register'!$A$2:$A$39,0))} -> PostgreSQL accessible with empty and default credentials | I24: [pgsql-empty-password] [javascript] [critical] 192.168.164.129:5432
A25: 21 | B25: netbios-udp-detect | C25: javascript | D25: Info | E25: 192.168.164.129:137 | F25: ["NetBIOS Name Service Detected"] | G25: R38 | H25: {=INDEX('Risk Register'!$C$2:$C$39,MATCH(G25,'Risk Register'!$A$2:$A$39,0))} -> NetBIOS and RPC information disclosure | I25: [netbios-udp-detect] [javascript] [info] 192.168.164.129:137 ["NetBIOS Name Service Detected"]
A26: 22 | B26: rpc-udp-detect | C26: javascript | D26: Info | E26: 192.168.164.129:111 | F26: ["RPC Portmapper UDP Detected"] | G26: R38 | H26: {=INDEX('Risk Register'!$C$2:$C$39,MATCH(G26,'Risk Register'!$A$2:$A$39,0))} -> NetBIOS and RPC information disclosure | I26: [rpc-udp-detect] [javascript] [info] 192.168.164.129:111 ["RPC Portmapper UDP Detected"]
A27: 23 | B27: CVE-2004-2687 | C27: tcp | D27: High | E27: 192.168.164.129:3632 | G27: R05 | H27: {=INDEX('Risk Register'!$C$2:$C$39,MATCH(G27,'Risk Register'!$A$2:$A$39,0))} -> distccd remote command execution | I27: [CVE-2004-2687] [tcp] [high] 192.168.164.129:3632
A28: 24 | B28: CVE-2015-1419:version | C28: tcp | D28: Medium | E28: 192.168.164.129:21 | F28: ["2.3.4"] | G28: R30 | H28: {=INDEX('Risk Register'!$C$2:$C$39,MATCH(G28,'Risk Register'!$A$2:$A$39,0))} -> Additional vsftpd CVEs flagged by version match | I28: [CVE-2015-1419:version] [tcp] [medium] 192.168.164.129:21 ["2.3.4"]
A29: 25 | B29: CVE-2021-30047:version | C29: tcp | D29: High | E29: 192.168.164.129:21 | F29: ["2.3.4"] | G29: R30 | H29: {=INDEX('Risk Register'!$C$2:$C$39,MATCH(G29,'Risk Register'!$A$2:$A$39,0))} -> Additional vsftpd CVEs flagged by version match | I29: [CVE-2021-30047:version] [tcp] [high] 192.168.164.129:21 ["2.3.4"]
A30: 26 | B30: ftp-weak-credentials | C30: tcp | D30: High | E30: 192.168.164.129:21 | F30: password='password', username='ftp' | G30: R10 | H30: {=INDEX('Risk Register'!$C$2:$C$39,MATCH(G30,'Risk Register'!$A$2:$A$39,0))} -> Anonymous FTP login and weak FTP credentials | I30: [ftp-weak-credentials] [tcp] [high] 192.168.164.129:21 [password="password",username="ftp"]
A31: 27 | B31: ftp-weak-credentials | C31: tcp | D31: High | E31: 192.168.164.129:21 | F31: password='default', username='ftp' | G31: R10 | H31: {=INDEX('Risk Register'!$C$2:$C$39,MATCH(G31,'Risk Register'!$A$2:$A$39,0))} -> Anonymous FTP login and weak FTP credentials | I31: [ftp-weak-credentials] [tcp] [high] 192.168.164.129:21 [password="default",username="ftp"]
A32: 28 | B32: ftp-weak-credentials | C32: tcp | D32: High | E32: 192.168.164.129:21 | F32: password='nas', username='ftp' | G32: R10 | H32: {=INDEX('Risk Register'!$C$2:$C$39,MATCH(G32,'Risk Register'!$A$2:$A$39,0))} -> Anonymous FTP login and weak FTP credentials | I32: [ftp-weak-credentials] [tcp] [high] 192.168.164.129:21 [password="nas",username="ftp"]
A33: 29 | B33: ftp-detect | C33: tcp | D33: Info | E33: 192.168.164.129:21 | G33: R10 | H33: {=INDEX('Risk Register'!$C$2:$C$39,MATCH(G33,'Risk Register'!$A$2:$A$39,0))} -> Anonymous FTP login and weak FTP credentials | I33: [ftp-detect] [tcp] [info] 192.168.164.129:21
A34: 30 | B34: vsftpd-detect:version | C34: tcp | D34: Info | E34: 192.168.164.129:21 | F34: ["2.3.4"] | G34: R01 | H34: {=INDEX('Risk Register'!$C$2:$C$39,MATCH(G34,'Risk Register'!$A$2:$A$39,0))} -> vsftpd 2.3.4 backdoor detected | I34: [vsftpd-detect:version] [tcp] [info] 192.168.164.129:21 ["2.3.4"]
A35: 31 | B35: nfs-v3-exposed | C35: tcp | D35: Info | E35: 192.168.164.129:2049 | G35: R21 | H35: {=INDEX('Risk Register'!$C$2:$C$39,MATCH(G35,'Risk Register'!$A$2:$A$39,0))} -> NFS and RPC portmapper services exposed | I35: [nfs-v3-exposed] [tcp] [info] 192.168.164.129:2049
A36: 32 | B36: pgsql-detect | C36: tcp | D36: Info | E36: 192.168.164.129:5432 | G36: R15 | H36: {=INDEX('Risk Register'!$C$2:$C$39,MATCH(G36,'Risk Register'!$A$2:$A$39,0))} -> Legacy database services exposed to the network | I36: [pgsql-detect] [tcp] [info] 192.168.164.129:5432
A37: 33 | B37: openssh-detect | C37: tcp | D37: Info | E37: 192.168.164.129:22 | F37: ["SSH-2.0-OpenSSH_4.7p1 Debian-8ubuntu1"] | G37: R26 | H37: {=INDEX('Risk Register'!$C$2:$C$39,MATCH(G37,'Risk Register'!$A$2:$A$39,0))} -> Legacy OpenSSH 4.7p1 with 1024-bit DSA host key | I37: [openssh-detect] [tcp] [info] 192.168.164.129:22 ["SSH-2.0-OpenSSH_4.7p1 Debian-8ubuntu1"]
A38: 34 | B38: vnc-service-detect | C38: tcp | D38: Info | E38: 192.168.164.129:5900 | F38: ["RFB 003.003"] | G38: R06 | H38: {=INDEX('Risk Register'!$C$2:$C$39,MATCH(G38,'Risk Register'!$A$2:$A$39,0))} -> VNC remote desktop with weak password and weak protocol | I38: [vnc-service-detect] [tcp] [info] 192.168.164.129:5900 ["RFB 003.003"]
A39: 35 | B39: CVE-2020-1938 | C39: tcp | D39: Critical | E39: 192.168.164.129:8009 | G39: R04 | H39: {=INDEX('Risk Register'!$C$2:$C$39,MATCH(G39,'Risk Register'!$A$2:$A$39,0))} -> Apache JServ (AJP) 'Ghostcat' vulnerability | I39: [CVE-2020-1938] [tcp] [critical] 192.168.164.129:8009
A40: 36 | B40: smtp-detect | C40: tcp | D40: Info | E40: 192.168.164.129:25 | G40: R32 | H40: {=INDEX('Risk Register'!$C$2:$C$39,MATCH(G40,'Risk Register'!$A$2:$A$39,0))} -> SMTP user enumeration commands enabled (VRFY, ETRN) | I40: [smtp-detect] [tcp] [info] 192.168.164.129:25
A41: 37 | B41: esmtp-detect | C41: tcp | D41: Info | E41: 192.168.164.129:25 | G41: R32 | H41: {=INDEX('Risk Register'!$C$2:$C$39,MATCH(G41,'Risk Register'!$A$2:$A$39,0))} -> SMTP user enumeration commands enabled (VRFY, ETRN) | I41: [esmtp-detect] [tcp] [info] 192.168.164.129:25
...

Sheet Nikto Results
A1: Nikto Scan Results (27 items)
A2: Nikto v2.5.0, http://192.168.164.129:80, 22 Oct 2026 05:30:48 - 05:31:40 (GMT-4); 8,910 requests, 0 errors, 27 items reported. Server: Apache/2.2.8 (Ubuntu) DAV/2.
A4: # | B4: Finding reported by Nikto | C4: Path | D4: Category | E4: Mapped finding
A5: 1 | B5: X-Powered-By header retrieved: PHP/5.2.4-2ubuntu5.10 | C5: / | D5: Information disclosure | E5: R35
A6: 2 | B6: Anti-clickjacking X-Frame-Options header not present | C6: / | D6: Missing header | E6: R34
A7: 3 | B7: X-Content-Type-Options header not set (MIME sniffing) | C7: / | D7: Missing header | E7: R34
A8: 4 | B8: Apache/2.2.8 outdated (current is at least 2.4.54; 2.2.34 is EOL for the 2.x branch) | C8: / | D8: Outdated software | E8: R14
A9: 5 | B9: Uncommon header 'tcn' found, with contents: list | C9: /index | D9: Information disclosure | E9: R35
A10: 6 | B10: mod_negotiation enabled with MultiViews; alternative 'index.php' found (file-name brute forcing) | C10: /index | D10: Misconfiguration | E10: R35
A11: 7 | B11: Server returns a valid response with junk HTTP methods (KOVKERUA); possible false positive | C11: / | D11: Behaviour / possible false positive | E11: R35
A12: 8 | B12: HTTP TRACE method active (suggests vulnerability to XST) | C12: / | D12: Insecure method | E12: R33
A13: 9 | B13: Output from phpinfo() found | C13: /phpinfo.php | D13: Information disclosure | E13: R23
