Workbook

Sheet Cover
A1: Lab 3b: Advanced Cybersecurity Risk Quantification – SecureBank Financial / SecureMobile
A4: Prepared by (name) | B4: Oluwatosin Olajubu
A5: Registration number | B5: C11/26/CGRCE/217602
A6: Date | B6: 27 October 2026
A7: Role in scenario | B7: Lead GRC Analyst, SecureBank Financial (reviewed by CISO and CFO)
A9: Colour code
A10: Blue text | B10: Hard-coded input taken from the lab brief (SUPPLIED figure)
A11: Blue text on yellow | B11: Analyst ASSUMPTION (not in the brief) – change it and everything recalculates
A12: Black text | B12: Formula on the same sheet
A13: Green text | B13: Formula that pulls from another sheet
A15: Sheet guide
A16: Inputs | B16: All supplied figures and analyst assumptions in one place (Task 1 inputs)
A17: Assumptions | B17: Assumption register: what was assumed, why, and what happens if it is wrong
A18: Risk_Calc | B18: Task 1 – SLE, ARO, ALE per vulnerability with working shown
A19: Risk_Matrix | B19: Task 2 – risk prioritisation matrix and probability-impact heat map
A20: Control_Analysis | B20: Task 4 – step-by-step cost-benefit analysis: risk reduction, residual risk, ROI, payback
A21: Timeline | B21: Task 5 – month-by-month risk reduction over time (line graph data)
A22: Gantt | B22: Task 7 – risk treatment plan (30 days / 90 days / 1 year)
A23: Budget_Optimiser | B23: Bonus – optimal control selection under budget constraints (all 8 combinations tested)
A24: Sensitivity | B24: Break-even and what-if tables that stress-test the assumptions
A25: Chart_Data | B25: Tables feeding the charts
A26: Charts | B26: Native Excel charts for Tasks 3 and 5 and the required visualisations
A27: Dashboard | B27: Task 6 – one-page executive dashboard
A29: Core formulas used
A30: SLE (Single Loss Expectancy) = impact driver A × impact driver B (e.g. records × cost per record)
A31: ARO (Annual Rate of Occurrence) = supplied exploit probability, read as expected incidents per year
A32: ALE (Annualised Loss Expectancy) = SLE × ARO
A33: Annual risk reduction = baseline ALE of the finding the control addresses × control effectiveness
A34: Residual ALE = baseline ALE − annual risk reduction
A35: Year-1 cost = initial investment + annual maintenance; 3-year TCO = initial + maintenance × 3
A36: ROI = (benefit − cost) ÷ cost (shown for Year 1 and over the 3-year horizon)
A37: Payback period (years) = initial investment ÷ (annual risk reduction − annual maintenance)

Sheet Dashboard
A1: Executive Risk Dashboard – SecureMobile Banking Platform
A2: ="Prepared by: "&Cover!B4&" | Registration no.: "&Cover!B5&" | Date: "&Cover!B6&" | For: CISO and CFO" -> Prepared by: Oluwatosin Olajubu | Registration no.: C11/26/CGRCE/217602 | Date: 27 October 2026 | For: CISO and CFO
A4: Baseline ALE ($/yr) | B4: Residual ALE after controls ($/yr) | C4: Annual risk reduction ($/yr) | D4: Risk reduction (%) | E4: Total initial investment ($) | F4: Portfolio Year-1 ROI (%) | G4: Portfolio payback (days)
A5: =Risk_Calc!I8 -> 35000000 | B5: =Control_Analysis!F9 -> 8037500 | C5: =Control_Analysis!F8 -> 26962500 | D5: =Control_Analysis!F7 -> 0.77035714 | E5: =Control_Analysis!F10 -> 700000 | F5: =Control_Analysis!F14 -> 32.493789 | G5: =Control_Analysis!F21 -> 9.5131714
A7: Top 3 risks with financial impact (ranked by ALE)
A8: Rank | B8: Vulnerability | C8: SLE ($) | D8: ARO (per year) | E8: ALE ($ / year) | F8: Priority level
A9: 1 | B9: {=INDEX(Risk_Matrix!$B$5:$B$7,MATCH($A9,Risk_Matrix!$F$5:$F$7,0))} -> F2 – Database Injection Vulnerability | C9: {=INDEX(Risk_Matrix!$C$5:$C$7,MATCH($A9,Risk_Matrix!$F$5:$F$7,0))} -> 125000000 | D9: {=INDEX(Risk_Matrix!$D$5:$D$7,MATCH($A9,Risk_Matrix!$F$5:$F$7,0))} -> 0.25 | E9: {=INDEX(Risk_Matrix!$E$5:$E$7,MATCH($A9,Risk_Matrix!$F$5:$F$7,0))} -> 31250000 | F9: {=INDEX(Risk_Matrix!$M$5:$M$7,MATCH($A9,Risk_Matrix!$F$5:$F$7,0))} -> Critical
A10: 2 | B10: {=INDEX(Risk_Matrix!$B$5:$B$7,MATCH($A10,Risk_Matrix!$F$5:$F$7,0))} -> F3 – Session Hijacking | C10: {=INDEX(Risk_Matrix!$C$5:$C$7,MATCH($A10,Risk_Matrix!$F$5:$F$7,0))} -> 7500000 | D10: {=INDEX(Risk_Matrix!$D$5:$D$7,MATCH($A10,Risk_Matrix!$F$5:$F$7,0))} -> 0.4 | E10: {=INDEX(Risk_Matrix!$E$5:$E$7,MATCH($A10,Risk_Matrix!$F$5:$F$7,0))} -> 3000000 | F10: {=INDEX(Risk_Matrix!$M$5:$M$7,MATCH($A10,Risk_Matrix!$F$5:$F$7,0))} -> High
A11: 3 | B11: {=INDEX(Risk_Matrix!$B$5:$B$7,MATCH($A11,Risk_Matrix!$F$5:$F$7,0))} -> F1 – API Authentication Bypass | C11: {=INDEX(Risk_Matrix!$C$5:$C$7,MATCH($A11,Risk_Matrix!$F$5:$F$7,0))} -> 5000000 | D11: {=INDEX(Risk_Matrix!$D$5:$D$7,MATCH($A11,Risk_Matrix!$F$5:$F$7,0))} -> 0.15 | E11: {=INDEX(Risk_Matrix!$E$5:$E$7,MATCH($A11,Risk_Matrix!$F$5:$F$7,0))} -> 750000 | F11: {=INDEX(Risk_Matrix!$M$5:$M$7,MATCH($A11,Risk_Matrix!$F$5:$F$7,0))} -> Medium
A13: Recommended controls (ordered by risk reduction)
A14: Priority | B14: Control | C14: Initial cost ($) | D14: Annual maintenance ($) | E14: Annual risk reduction ($) | F14: Year-1 ROI (%) | G14: Payback (days) | H14: Decision
A15: 1 | B15: {=INDEX(Control_Analysis!$C$4:$E$4,MATCH($A15,Control_Analysis!$C$22:$E$22,0))} -> Web Application Firewall (WAF) | C15: {=INDEX(Control_Analysis!$C$10:$E$10,MATCH($A15,Control_Analysis!$C$22:$E$22,0))} -> 150000 | D15: {=INDEX(Control_Analysis!$C$11:$E$11,MATCH($A15,Control_Analysis!$C$22:$E$22,0))} -> 25000 | E15: {=INDEX(Control_Analysis!$C$8:$E$8,MATCH($A15,Control_Analysis!$C$22:$E$22,0))} -> 23437500 | F15: {=INDEX(Control_Analysis!$C$14:$E$14,MATCH($A15,Control_Analysis!$C$22:$E$22,0))} -> 132.92857 | G15: {=INDEX(Control_Analysis!$C$21:$E$21,MATCH($A15,Control_Analysis!$C$22:$E$22,0))} -> 2.3384944 | H15: {=INDEX(Control_Analysis!$C$23:$E$23,MATCH($A15,Control_Analysis!$C$22:$E$22,0))} -> IMPLEMENT
A16: 2 | B16: {=INDEX(Control_Analysis!$C$4:$E$4,MATCH($A16,Control_Analysis!$C$22:$E$22,0))} -> Multi-Factor Authentication Enhancement | C16: {=INDEX(Control_Analysis!$C$10:$E$10,MATCH($A16,Control_Analysis!$C$22:$E$22,0))} -> 200000 | D16: {=INDEX(Control_Analysis!$C$11:$E$11,MATCH($A16,Control_Analysis!$C$22:$E$22,0))} -> 30000 | E16: {=INDEX(Control_Analysis!$C$8:$E$8,MATCH($A16,Control_Analysis!$C$22:$E$22,0))} -> 2850000 | F16: {=INDEX(Control_Analysis!$C$14:$E$14,MATCH($A16,Control_Analysis!$C$22:$E$22,0))} -> 11.391304 | G16: {=INDEX(Control_Analysis!$C$21:$E$21,MATCH($A16,Control_Analysis!$C$22:$E$22,0))} -> 25.886525 | H16: {=INDEX(Control_Analysis!$C$23:$E$23,MATCH($A16,Control_Analysis!$C$22:$E$22,0))} -> IMPLEMENT
A17: 3 | B17: {=INDEX(Control_Analysis!$C$4:$E$4,MATCH($A17,Control_Analysis!$C$22:$E$22,0))} -> Advanced API Security Gateway | C17: {=INDEX(Control_Analysis!$C$10:$E$10,MATCH($A17,Control_Analysis!$C$22:$E$22,0))} -> 350000 | D17: {=INDEX(Control_Analysis!$C$11:$E$11,MATCH($A17,Control_Analysis!$C$22:$E$22,0))} -> 50000 | E17: {=INDEX(Control_Analysis!$C$8:$E$8,MATCH($A17,Control_Analysis!$C$22:$E$22,0))} -> 675000 | F17: {=INDEX(Control_Analysis!$C$14:$E$14,MATCH($A17,Control_Analysis!$C$22:$E$22,0))} -> 0.6875 | G17: {=INDEX(Control_Analysis!$C$21:$E$21,MATCH($A17,Control_Analysis!$C$22:$E$22,0))} -> 204.4 | H17: {=INDEX(Control_Analysis!$C$23:$E$23,MATCH($A17,Control_Analysis!$C$22:$E$22,0))} -> IMPLEMENT
A18: Total | C18: =SUM(C15:C17) -> 700000 | D18: =SUM(D15:D17) -> 105000 | E18: =SUM(E15:E17) -> 26962500 | F18: =Control_Analysis!F14 -> 32.493789 | G18: =Control_Analysis!F21 -> 9.5131714
A19: ="Year-1 realised benefit with phased roll-out: $"&TEXT(Timeline!D22,"#,##0")&" loss avoided against $"&TEXT(Timeline!D23,"#,##0")&" control spend (net $"&TEXT(Timeline!D24,"#,##0")&")." -> Year-1 realised benefit with phased roll-out: $24,128,125 loss avoided against $782,917 control spend (net $23,345,208).

Sheet Inputs
A1: Inputs – supplied figures (blue) and my assumptions are colored (blue on yellow)
A2: Every calculation in this workbook reads from this sheet. Change a value here and all sheets, charts and the dashboard update.
A4: Parameter | B4: Value | C4: Unit | D4: Type | E4: Source / note
A5: A. System context
A6: Active customers | B6: 500000 | C6: customers | D6: Supplied | E6: Lab brief
A7: Average transaction value | B7: 2500 | C7: $ per transaction | D7: Supplied | E7: Lab brief
A8: Daily transactions | B8: 50000 | C8: transactions/day | D8: Supplied | E8: Lab brief
A9: Daily transaction value (derived) | B9: =B7*B8 -> 125000000 | C9: $ per day | D9: Derived | E9: Context only – not used in ALE (see assumption A-12)
A10: B. Critical Finding 1 – API Authentication Bypass
A11: Exploit probability | B11: 0.15 | C11: per year | D11: Supplied | E11: Lab brief (read as annual probability – assumption A-01)
A12: Maximum single incident loss | B12: 5000000 | C12: $ | D12: Supplied | E12: Lab brief
A13: Estimated detection time | B13: 48 | C13: hours | D13: Supplied | E13: Lab brief (context; not separately modelled – A-02)
A14: C. Critical Finding 2 – Database Injection Vulnerability
A15: Exploit probability | B15: 0.25 | C15: per year | D15: Supplied | E15: Lab brief
A16: Records at risk | B16: 500000 | C16: customer profiles | D16: Supplied | E16: Lab brief
A17: Cost per record (regulatory + notification) | B17: 250 | C17: $ per record | D17: Supplied | E17: Lab brief
A18: D. Critical Finding 3 – Session Hijacking
A19: Exploit probability | B19: 0.4 | C19: per year | D19: Supplied | E19: Lab brief
A20: Accounts at risk (simultaneous sessions) | B20: 5000 | C20: accounts | D20: Supplied | E20: Lab brief
A21: Average loss per account | B21: 1500 | C21: $ per account | D21: Supplied | E21: Lab brief
A22: E. Control options (cost and effectiveness supplied; finding mapping and go-live are assumptions)
A23: Control | B23: Initial cost ($) | C23: Effectiveness (risk reduction) | D23: Annual maintenance ($) | E23: Finding addressed (ASSUMPTION A-05) | F23: Go-live month (ASSUMPTION – derived from Gantt)
A24: Advanced API Security Gateway | B24: 350000 | C24: 0.9 | D24: 50000 | E24: F1 | F24: =ROUNDUP(Gantt!F12/$B$38,0) -> 3
A25: Web Application Firewall (WAF) | B25: 150000 | C25: 0.75 | D25: 25000 | E25: F2 | F25: =ROUNDUP(Gantt!F7/$B$38,0) -> 1
A26: Multi-Factor Authentication Enhancement | B26: 200000 | C26: 0.95 | D26: 30000 | E26: F3 | F26: =ROUNDUP(Gantt!F10/$B$38,0) -> 3
A27: F. Analyst assumptions (all adjustable)
A28: ROI / total-cost-of-ownership horizon | B28: 3 | C28: years | D28: Assumption | E28: A-09: typical 3-year security investment horizon
A29: Maximum acceptable payback period | B29: 1 | C29: years | D29: Assumption | E29: A-09: decision hurdle for 'Implement'
A30: Minimum acceptable ROI over horizon | B30: 1 | C30: ratio (1 = 100%) | D30: Assumption | E30: A-09: decision hurdle for 'Implement'
A31: Risk priority 'Critical' if ALE ≥ | B31: 10000000 | C31: $ per year | D31: Assumption | E31: A-10
A32: Risk priority 'High' if ALE ≥ | B32: 1000000 | C32: $ per year | D32: Assumption | E32: A-10
A33: Risk priority 'Medium' if ALE ≥ | B33: 100000 | C33: $ per year | D33: Assumption | E33: A-10 (below this = Low)
A34: Probability band 'High' if ARO ≥ | B34: 0.3 | C34: per year | D34: Assumption | E34: A-10
A35: Probability band 'Medium' if ARO ≥ | B35: 0.1 | C35: per year | D35: Assumption | E35: A-10 (below this = Low)
A36: Impact band 'High' if SLE ≥ | B36: 10000000 | C36: $ | D36: Assumption | E36: A-10
A37: Impact band 'Medium' if SLE ≥ | B37: 1000000 | C37: $ | D37: Assumption | E37: A-10 (below this = Low)
A38: Days per month (timeline conversion) | B38: 30 | C38: days | D38: Assumption | E38: A-11
A39: Finding 1: incidents per loss event (multiplier) | B39: 1 | C39: x | D39: Assumption | E39: A-02: the brief gives one maximum single-incident loss, so multiplier = 1

Sheet Assumptions
A1: Assumption register – supplied figures vs my own assumptions
A2: Anything not stated in the lab brief is listed here so the CISO / CFO can challenge it.
A4: ID | B4: Assumption | C4: Rationale | D4: Effect if the assumption is wrong
A5: A-01 | B5: Each supplied 'exploit probability' is the probability of one exploitation event in a 12-month period, so ARO = that probability. | C5: The brief gives probabilities but not an explicit time basis; annual is the standard ALE convention. | D5: ARO and every ALE scale proportionally (see Sensitivity).
A6: A-02 | B6: Finding 1 SLE = the supplied maximum single-incident loss ($5,000,000) × 1 incident. The 48-hour detection time is context and is not used to derive a different loss. | C6: The brief provides the loss figure directly; using it is the conservative (worst-case) reading. | D6: If actual loss per event is lower, ALE and API Gateway ROI fall (see Sensitivity table 3).
A7: A-03 | B7: Finding 2 SLE = 500,000 records × $250 = full-population breach in one event. | C7: Brief states 'Records at Risk: 500,000' and cost per record; full exposure is the supplied worst case. | D7: A smaller breach lowers ALE; WAF stays justified at very low scales (Sensitivity table 2).
A8: A-04 | B8: Finding 3 SLE = 5,000 accounts × $1,500 = all at-risk accounts compromised in one event. | C8: Brief states accounts at risk and average loss per account. | D8: Smaller compromise lowers ALE proportionally.
A9: A-05 | B9: Control mapping: API Gateway → Finding 1; WAF → Finding 2; MFA → Finding 3. No control reduces any other finding. | C9: Matches the brief's wording (API vulnerabilities / web vulnerabilities / account takeover). Ignoring cross-benefits is conservative. | D9: Cross-benefits would raise risk reduction and ROI.
A10: A-06 | B10: Effectiveness is applied as a proportional reduction of the finding's ALE (lower likelihood); SLE is unchanged. | C10: The brief gives '% reduction in vulnerabilities', a likelihood-type measure. | D10: If effectiveness only partly applies, reduction and ROI fall proportionally.
A11: A-07 | B11: Year-1 cost = initial investment + one year of maintenance. Costs are not discounted, inflated, taxed or given a residual value. Maintenance is paid every year from go-live. | C11: Keeps the maths transparent and reproducible by hand. | D11: Discounting would slightly lower multi-year ROI.
A12: A-08 | B12: ROI = (benefit − cost) ÷ cost. Payback = initial investment ÷ (annual risk reduction − annual maintenance), assuming a constant annual benefit. | C12: Standard security-investment ROI; payback measured on steady-state benefit. | D12: Benefit is probabilistic, so realised payback may vary.
A13: A-09 | B13: Decision hurdle: 'Implement' if payback ≤ 1 year AND ROI over the 3-year horizon ≥ 100%. | C13: A typical CFO-style hurdle; editable on Inputs. | D13: Changing the hurdle can change the recommendation column.
A14: A-10 | B14: Risk priority bands: Critical ≥ $10M ALE, High ≥ $1M, Medium ≥ $100k, else Low. Probability: High ≥ 30%, Medium ≥ 10%. Impact (SLE): High ≥ $10M, Medium ≥ $1M. | C14: The brief does not define bands; these are proportionate to the scale of the data set. | D14: Different thresholds can change labels but not the ALE ranking.
A15: A-11 | B15: Timeline: controls go live when their deployment tasks finish on the Gantt chart (WAF day 30; MFA and API Gateway day 90), protect from the following month, 30 days = 1 month, effectiveness constant. | C15: Derived from the risk treatment plan so the line graph and Gantt agree. | D15: Slower delivery delays Year-1 benefit.
... A18: A-14 | B18: Budget optimiser compares capital (initial) cost only and tests all 8 combinations of the 3 controls. | C18: Exhaustive search is exact for 3 controls. | D18: Including maintenance in the budget would tighten feasibility.

Sheet Risk_Calc
A1: Task 1 – Annualised Loss Expectancy (ALE) per vulnerability
A2: SLE = Driver A × Driver B | ARO = exploit probability per year | ALE = SLE × ARO. The 'Working shown' column writes the substituted numbers out.
A4: ID | B4: Vulnerability | C4: Driver A (what it is) | D4: Driver A value | E4: Driver B (what it is) | F4: Driver B value | G4: SLE ($) = A × B | H4: ARO (per year) | I4: ALE ($ / year) = SLE × ARO | J4: Share of total ALE | K4: ALE rank | L4: Working shown
A5: F1 | B5: F1 – API Authentication Bypass | C5: Maximum single incident loss ($) | D5: =Inputs!B12 -> 5000000 | E5: Incidents per loss event (x) | F5: =Inputs!B39 -> 1 | G5: =D5*F5 -> 5000000 | H5: =Inputs!B11 -> 0.15 | I5: =G5*H5 -> 750000 | J5: =I5/$I$8 -> 0.021428571 | K5: =RANK(I5,$I$5:$I$7) -> 3 | L5: ="SLE = "&TEXT(D5,"#,##0")&" × "&TEXT(F5,"#,##0")&" = $"&TEXT(G5,"#,##0")&" | ALE = $"&TEXT(G5,"#,##0")&" × "&TEXT(H5,"0%")&" = $"&TEXT(I5,"#,##0") -> SLE = 5,000,000 × 1 = $5,000,000 | ALE = $5,000,000 × 15% = $750,000
A6: F2 | B6: F2 – Database Injection Vulnerability | C6: Records at risk (records) | D6: =Inputs!B16 -> 500000 | E6: Cost per record ($) | F6: =Inputs!B17 -> 250 | G6: =D6*F6 -> 125000000 | H6: =Inputs!B15 -> 0.25 | I6: =G6*H6 -> 31250000 | J6: =I6/$I$8 -> 0.89285714 | K6: =RANK(I6,$I$5:$I$7) -> 1 | L6: ="SLE = "&TEXT(D6,"#,##0")&" × "&TEXT(F6,"#,##0")&" = $"&TEXT(G6,"#,##0")&" | ALE = $"&TEXT(G6,"#,##0")&" × "&TEXT(H6,"0%")&" = $"&TEXT(I6,"#,##0") -> SLE = 500,000 × 250 = $125,000,000 | ALE = $125,000,000 × 25% = $31,250,000
A7: F3 | B7: F3 – Session Hijacking | C7: Accounts at risk (accounts) | D7: =Inputs!B20 -> 5000 | E7: Average loss per account ($) | F7: =Inputs!B21 -> 1500 | G7: =D7*F7 -> 7500000 | H7: =Inputs!B19 -> 0.4 | I7: =G7*H7 -> 3000000 | J7: =I7/$I$8 -> 0.085714286 | K7: =RANK(I7,$I$5:$I$7) -> 2 | L7: ="SLE = "&TEXT(D7,"#,##0")&" × "&TEXT(F7,"#,##0")&" = $"&TEXT(G7,"#,##0")&" | ALE = $"&TEXT(G7,"#,##0")&" × "&TEXT(H7,"0%")&" = $"&TEXT(I7,"#,##0") -> SLE = 5,000 × 1,500 = $7,500,000 | ALE = $7,500,000 × 40% = $3,000,000
B8: TOTAL | I8: =SUM(I5:I7) -> 35000000 | J8: =SUM(J5:J7) -> 1 | L8: ="Total ALE = $"&TEXT(I5,"#,##0")&" + $"&TEXT(I6,"#,##0")&" + $"&TEXT(I7,"#,##0")&" = $"&TEXT(I8,"#,##0") -> Total ALE = $750,000 + $31,250,000 + $3,000,000 = $35,000,000
A10: Reading the table: SLE is the loss from ONE incident; ARO is how many incidents to expect per year; ALE is the expected yearly loss (a long-run average, not a prediction of any one year).

Sheet Risk_Matrix
A1: Task 2 – Risk prioritisation matrix and probability-impact heat map
A2: Priority level is set by ALE size (thresholds on Inputs). The heat map places each finding by probability band (ARO) and impact band (SLE).
A4: ID | B4: Vulnerability | C4: SLE ($) | D4: ARO (per year) | E4: ALE ($ / year) | F4: ALE rank | G4: Probability band | H4: Impact band | I4: P score (1-3) | J4: I score (1-3) | K4: Risk score = P × I | L4: Heat-map rating | M4: Risk priority level (by ALE)
A5: =Risk_Calc!A5 -> F1 | B5: =Risk_Calc!B5 -> F1 – API Authentication Bypass | C5: =Risk_Calc!G5 -> 5000000 | D5: =Risk_Calc!H5 -> 0.15 | E5: =Risk_Calc!I5 -> 750000 | F5: =RANK(E5,$E$5:$E$7) -> 3 | G5: =IF(D5>=Inputs!$B$34,"High",IF(D5>=Inputs!$B$35,"Medium","Low")) -> Medium | H5: =IF(C5>=Inputs!$B$36,"High",IF(C5>=Inputs!$B$37,"Medium","Low")) -> Medium | I5: =IF(G5="High",3,IF(G5="Medium",2,1)) -> 2 | J5: =IF(H5="High",3,IF(H5="Medium",2,1)) -> 2 | K5: =I5*J5 -> 4 | L5: =IF(K5>=6,"High",IF(K5>=3,"Medium","Low")) -> Medium | M5: =IF(E5>=Inputs!$B$31,"Critical",IF(E5>=Inputs!$B$32,"High",IF(E5>=Inputs!$B$33,"Medium","Low"))) -> Medium
A6: =Risk_Calc!A6 -> F2 | B6: =Risk_Calc!B6 -> F2 – Database Injection Vulnerability | C6: =Risk_Calc!G6 -> 125000000 | D6: =Risk_Calc!H6 -> 0.25 | E6: =Risk_Calc!I6 -> 31250000 | F6: =RANK(E6,$E$5:$E$7) -> 1 | G6: =IF(D6>=Inputs!$B$34,"High",IF(D6>=Inputs!$B$35,"Medium","Low")) -> Medium | H6: =IF(C6>=Inputs!$B$36,"High",IF(C6>=Inputs!$B$37,"Medium","Low")) -> High | I6: =IF(G6="High",3,IF(G6="Medium",2,1)) -> 2 | J6: =IF(H6="High",3,IF(H6="Medium",2,1)) -> 3 | K6: =I6*J6 -> 6 | L6: =IF(K6>=6,"High",IF(K6>=3,"Medium","Low")) -> High | M6: =IF(E6>=Inputs!$B$31,"Critical",IF(E6>=Inputs!$B$32,"High",IF(E6>=Inputs!$B$33,"Medium","Low"))) -> Critical
A7: =Risk_Calc!A7 -> F3 | B7: =Risk_Calc!B7 -> F3 – Session Hijacking | C7: =Risk_Calc!G7 -> 7500000 | D7: =Risk_Calc!H7 -> 0.4 | E7: =Risk_Calc!I7 -> 3000000 | F7: =RANK(E7,$E$5:$E$7) -> 2 | G7: =IF(D7>=Inputs!$B$34,"High",IF(D7>=Inputs!$B$35,"Medium","Low")) -> High | H7: =IF(C7>=Inputs!$B$36,"High",IF(C7>=Inputs!$B$37,"Medium","Low")) -> Medium | I7: =IF(G7="High",3,IF(G7="Medium",2,1)) -> 3 | J7: =IF(H7="High",3,IF(H7="Medium",2,1)) -> 2 | K7: =I7*J7 -> 6 | L7: =IF(K7>=6,"High",IF(K7>=3,"Medium","Low")) -> High | M7: =IF(E7>=Inputs!$B$31,"Critical",IF(E7>=Inputs!$B$32,"High",IF(E7>=Inputs!$B$33,"Medium","Low"))) -> High
A9: Probability-impact heat map (cells show which findings fall in each band)
B10: Impact (SLE) ↓ | Probability (ARO) → | C10: ="Low (< "&TEXT(Inputs!B35,"0%")&")" -> Low (< 10%) | D10: ="Medium ("&TEXT(Inputs!B35,"0%")&" to < "&TEXT(Inputs!B34,"0%")&")" -> Medium (10% to < 30%) | E10: ="High (≥ "&TEXT(Inputs!B34,"0%")&")" -> High (≥ 30%)
B11: ="High (SLE ≥ $"&TEXT(Inputs!B36,"#,##0")&")" -> High (SLE ≥ $10,000,000) | C11: =TRIM(IF(AND($J$5=3,$I$5=1),"F1 ","")&IF(AND($J$6=3,$I$6=1),"F2 ","")&IF(AND($J$7=3,$I$7=1),"F3 ","")) | D11: =TRIM(IF(AND($J$5=3,$I$5=2),"F1 ","")&IF(AND($J$6=3,$I$6=2),"F2 ","")&IF(AND($J$7=3,$I$7=2),"F3 ","")) -> F2 | E11: =TRIM(IF(AND($J$5=3,$I$5=3),"F1 ","")&IF(AND($J$6=3,$I$6=3),"F2 ","")&IF(AND($J$7=3,$I$7=3),"F3 ",""))
B12: ="Medium ($"&TEXT(Inputs!B37,"#,##0")&" to < $"&TEXT(Inputs!B36,"#,##0")&")" -> Medium ($1,000,000 to < $10,000,000) | C12: =TRIM(IF(AND($J$5=2,$I$5=1),"F1 ","")&IF(AND($J$6=2,$I$6=1),"F2 ","")&IF(AND($J$7=2,$I$7=1),"F3 ","")) | D12: =TRIM(IF(AND($J$5=2,$I$5=2),"F1 ","")&IF(AND($J$6=2,$I$6=2),"F2 ","")&IF(AND($J$7=2,$I$7=2),"F3 ","")) -> F1 | E12: =TRIM(IF(AND($J$5=2,$I$5=3),"F1 ","")&IF(AND($J$6=2,$I$6=3),"F2 ","")&IF(AND($J$7=2,$I$7=3),"F3 ","")) -> F3
B13: ="Low (SLE < $"&TEXT(Inputs!B37,"#,##0")&")" -> Low (SLE < $1,000,000) | C13: =TRIM(IF(AND($J$5=1,$I$5=1),"F1 ","")&IF(AND($J$6=1,$I$6=1),"F2 ","")&IF(AND($J$7=1,$I$7=1),"F3 ","")) | D13: =TRIM(IF(AND($J$5=1,$I$5=2),"F1 ","")&IF(AND($J$6=1,$I$6=2),"F2 ","")&IF(AND($J$7=1,$I$7=2),"F3 ","")) | E13: =TRIM(IF(AND($J$5=1,$I$5=3),"F1 ","")&IF(AND($J$6=1,$I$6=3),"F2 ","")&IF(AND($J$7=1,$I$7=3),"F3 ",""))
A15: How to read: Risk score = P score × I score (Low = 1, Medium = 2, High = 3). Score ≥ 6 = High (red), 3-4 = Medium (amber), ≤ 2 = Low (green).
A16: Priority level (column M) uses ALE size instead, so a very large loss with moderate probability (F2) is flagged Critical.

Sheet Control_Analysis
A1: Task 4 – Control cost-benefit analysis (step by step)
A2: Read each column top to bottom: every step uses the steps above it. Column B states the formula in words.
A4: Step | B4: Calculation | C4: =Inputs!A24 -> Advanced API Security Gateway | D4: =Inputs!A25 -> Web Application Firewall (WAF) | E4: =Inputs!A26 -> Multi-Factor Authentication Enhancement | F4: Portfolio (all 3 controls)
A5: Finding addressed | B5: Assumption A-05 (Inputs) | C5: =Inputs!E24 -> F1 | D5: =Inputs!E25 -> F2 | E5: =Inputs!E26 -> F3
A6: 1 Baseline ALE ($/yr) | B6: ALE of the finding addressed (from Risk_Calc) | C6: {=INDEX(Risk_Calc!$I$5:$I$7,MATCH(C5,Risk_Calc!$A$5:$A$7,0))} -> 750000 | D6: {=INDEX(Risk_Calc!$I$5:$I$7,MATCH(D5,Risk_Calc!$A$5:$A$7,0))} -> 31250000 | E6: {=INDEX(Risk_Calc!$I$5:$I$7,MATCH(E5,Risk_Calc!$A$5:$A$7,0))} -> 3000000 | F6: =SUM(C6:E6) -> 35000000
A7: 2 Effectiveness (%) | B7: Supplied in brief | C7: =Inputs!C24 -> 0.9 | D7: =Inputs!C25 -> 0.75 | E7: =Inputs!C26 -> 0.95 | F7: =F8/F6 -> 0.77035714
A8: 3 Annual risk reduction ($/yr) | B8: Step 1 × Step 2 | C8: =C6*C7 -> 675000 | D8: =D6*D7 -> 23437500 | E8: =E6*E7 -> 2850000 | F8: =SUM(C8:E8) -> 26962500
A9: 4 Residual ALE ($/yr) | B9: Step 1 − Step 3 | C9: =C6-C8 -> 75000 | D9: =D6-D8 -> 7812500 | E9: =E6-E8 -> 150000 | F9: =SUM(C9:E9) -> 8037500
A10: 5 Initial investment ($) | B10: Supplied in brief | C10: =Inputs!B24 -> 350000 | D10: =Inputs!B25 -> 150000 | E10: =Inputs!B26 -> 200000 | F10: =SUM(C10:E10) -> 700000
A11: 6 Annual maintenance ($/yr) | B11: Supplied in brief | C11: =Inputs!D24 -> 50000 | D11: =Inputs!D25 -> 25000 | E11: =Inputs!D26 -> 30000 | F11: =SUM(C11:E11) -> 105000
A12: 7 Year-1 total cost ($) | B12: Step 5 + Step 6 | C12: =C10+C11 -> 400000 | D12: =D10+D11 -> 175000 | E12: =E10+E11 -> 230000 | F12: =SUM(C12:E12) -> 805000
A13: 8 Year-1 net benefit ($) | B13: Step 3 − Step 7 | C13: =C8-C12 -> 275000 | D13: =D8-D12 -> 23262500 | E13: =E8-E12 -> 2620000 | F13: =SUM(C13:E13) -> 26157500
A14: 9 Year-1 ROI (%) | B14: Step 8 ÷ Step 7 | C14: =C13/C12 -> 0.6875 | D14: =D13/D12 -> 132.92857 | E14: =E13/E12 -> 11.391304 | F14: =F13/F12 -> 32.493789
A15: 10 3-year total cost ($) | B15: Step 5 + (Step 6 × years) | C15: =C10+C11*Inputs!$B$28 -> 500000 | D15: =D10+D11*Inputs!$B$28 -> 225000 | E15: =E10+E11*Inputs!$B$28 -> 290000 | F15: =SUM(C15:E15) -> 1015000
A16: 11 3-year risk reduction ($) | B16: Step 3 × years | C16: =C8*Inputs!$B$28 -> 2025000 | D16: =D8*Inputs!$B$28 -> 70312500 | E16: =E8*Inputs!$B$28 -> 8550000 | F16: =SUM(C16:E16) -> 80887500
A17: 12 3-year net benefit ($) | B17: Step 11 − Step 10 | C17: =C16-C15 -> 1525000 | D17: =D16-D15 -> 70087500 | E17: =E16-E15 -> 8260000 | F17: =SUM(C17:E17) -> 79872500
A18: 13 3-year ROI (%) | B18: Step 12 ÷ Step 10 | C18: =C17/C15 -> 3.05 | D18: =D17/D15 -> 311.5 | E18: =E17/E15 -> 28.482759 | F18: =F17/F15 -> 78.692118
A19: 14 Payback period (years) | B19: Step 5 ÷ (Step 3 − Step 6) | C19: =IF(C8>C11,C10/(C8-C11),"n/a") -> 0.56 | D19: =IF(D8>D11,D10/(D8-D11),"n/a") -> 0.006406834 | E19: =IF(E8>E11,E10/(E8-E11),"n/a") -> 0.070921986 | F19: =IF(F8>F11,F10/(F8-F11),"n/a") -> 0.026063483
A20: 15 Payback period (months) | B20: Step 14 × 12 | C20: =IF(ISNUMBER(C19),C19*12,"n/a") -> 6.72 | D20: =IF(ISNUMBER(D19),D19*12,"n/a") -> 0.076882007 | E20: =IF(ISNUMBER(E19),E19*12,"n/a") -> 0.85106383 | F20: =IF(ISNUMBER(F19),F19*12,"n/a") -> 0.3127618
A21: 16 Payback period (days) | B21: Step 14 × 365 | C21: =IF(ISNUMBER(C19),C19*365,"n/a") -> 204.4 | D21: =IF(ISNUMBER(D19),D19*365,"n/a") -> 2.3384944 | E21: =IF(ISNUMBER(E19),E19*365,"n/a") -> 25.886525 | F21: =IF(ISNUMBER(F19),F19*365,"n/a") -> 9.5131714
A22: Implementation priority (1 = first) | B22: Rank of Step 3 (largest risk reduction first) | C22: =RANK(C8,$C$8:$E$8) -> 3 | D22: =RANK(D8,$C$8:$E$8) -> 1 | E22: =RANK(E8,$C$8:$E$8) -> 2
A23: Recommendation | B23: Implement if payback ≤ max payback AND 3-year ROI ≥ minimum (Inputs B29, B30) | C23: =IF(AND(ISNUMBER(C19),C19<=Inputs!$B$29,C18>=Inputs!$B$30),"IMPLEMENT","DO NOT IMPLEMENT") -> IMPLEMENT | D23: =IF(AND(ISNUMBER(D19),D19<=Inputs!$B$29,D18>=Inputs!$B$30),"IMPLEMENT","DO NOT IMPLEMENT") -> IMPLEMENT | E23: =IF(AND(ISNUMBER(E19),E19<=Inputs!$B$29,E18>=Inputs!$B$30),"IMPLEMENT","DO NOT IMPLEMENT") -> IMPLEMENT | F23: =IF(COUNTIF(C23:E23,"IMPLEMENT")=3,"All 3 justified","Review") -> All 3 justified
A24: Go-live month (assumption, from Gantt) | B24: Month the control becomes operational | C24: =Inputs!F24 -> 3 | D24: =Inputs!F25 -> 1 | E24: =Inputs!F26 -> 3
A26: Substituted working (the same steps with the numbers written in)
A27: Step 3 – risk reduction | C27: ="$"&TEXT(C6,"#,##0")&" × "&TEXT(C7,"0%")&" = $"&TEXT(C8,"#,##0") -> $750,000 × 90% = $675,000 | D27: ="$"&TEXT(D6,"#,##0")&" × "&TEXT(D7,"0%")&" = $"&TEXT(D8,"#,##0") -> $31,250,000 × 75% = $23,437,500 | E27: ="$"&TEXT(E6,"#,##0")&" × "&TEXT(E7,"0%")&" = $"&TEXT(E8,"#,##0") -> $3,000,000 × 95% = $2,850,000
A28: Step 9 – Year-1 ROI | C28: ="($"&TEXT(C8,"#,##0")&" − $"&TEXT(C12,"#,##0")&") ÷ $"&TEXT(C12,"#,##0")&" = "&TEXT(C14,"#,##0.0%") -> ($675,000 − $400,000) ÷ $400,000 = 68.8% | D28: ="($"&TEXT(D8,"#,##0")&" − $"&TEXT(D12,"#,##0")&") ÷ $"&TEXT(D12,"#,##0")&" = "&TEXT(D14,"#,##0.0%") -> ($23,437,500 − $175,000) ÷ $175,000 = 13,292.9% | E28: ="($"&TEXT(E8,"#,##0")&" − $"&TEXT(E12,"#,##0")&") ÷ $"&TEXT(E12,"#,##0")&" = "&TEXT(E14,"#,##0.0%") -> ($2,850,000 − $230,000) ÷ $230,000 = 1,139.1%
A29: Step 13 – 3-year ROI | C29: ="($"&TEXT(C16,"#,##0")&" − $"&TEXT(C15,"#,##0")&") ÷ $"&TEXT(C15,"#,##0")&" = "&TEXT(C18,"#,##0.0%") -> ($2,025,000 − $500,000) ÷ $500,000 = 305.0% | D29: ="($"&TEXT(D16,"#,##0")&" − $"&TEXT(D15,"#,##0")&") ÷ $"&TEXT(D15,"#,##0")&" = "&TEXT(D18,"#,##0.0%") -> ($70,312,500 − $225,000) ÷ $225,000 = 31,150.0% | E29: ="($"&TEXT(E16,"#,##0")&" − $"&TEXT(E15,"#,##0")&") ÷ $"&TEXT(E15,"#,##0")&" = "&TEXT(E18,"#,##0.0%") -> ($8,550,000 − $290,000) ÷ $290,000 = 2,848.3%
A30: Step 14 – payback | C30: ="$"&TEXT(C10,"#,##0")&" ÷ ($"&TEXT(C8,"#,##0")&" − $"&TEXT(C11,"#,##0")&") = "&TEXT(C19,"0.000")&" years = "&TEXT(C21,"0.0")&" days" -> $350,000 ÷ ($675,000 − $50,000) = 0.560 years = 204.4 days | D30: ="$"&TEXT(D10,"#,##0")&" ÷ ($"&TEXT(D8,"#,##0")&" − $"&TEXT(D11,"#,##0")&") = "&TEXT(D19,"0.000")&" years = "&TEXT(D21,"0.0")&" days" -> $150,000 ÷ ($23,437,500 − $25,000) = 0.006 years = 2.3 days | E30: ="$"&TEXT(E10,"#,##0")&" ÷ ($"&TEXT(E8,"#,##0")&" − $"&TEXT(E11,"#,##0")&") = "&TEXT(E19,"0.000")&" years = "&TEXT(E21,"0.0")&" days" -> $200,000 ÷ ($2,850,000 − $30,000) = 0.071 years = 25.9 days
A32: Note: ROI here is (risk reduction − cost) ÷ cost. Because the benefit of WAF is very large relative to its cost, its ROI is extremely high; see the Sensitivity sheet for how far the assumptions can fall before the control stops paying back.

Sheet Timeline
A1: Task 5 – Risk reduction over time (monthly expected loss, first 12 months)
A2: A control protects from the month AFTER its go-live month. Monthly expected loss = ALE ÷ 12 × (1 − effectiveness × live flag).
A4: Month | B4: API Gateway live? (1/0) | C4: WAF live? (1/0) | D4: MFA live? (1/0) | E4: F1 baseline loss ($/mo) | F4: F2 baseline loss ($/mo) | G4: F3 baseline loss ($/mo) | H4: Total baseline loss ($/mo) | I4: Expected loss WITH controls ($/mo) | J4: Cumulative loss – no controls ($) | K4: Cumulative loss – with controls ($) | L4: Cumulative loss avoided ($) | M4: Control spend this month ($) | N4: Cumulative control spend ($) | O4: Cumulative net benefit ($)
A5: 0 | B5: =IF($A5>Inputs!$F$24,1,0) -> 0 | C5: =IF($A5>Inputs!$F$25,1,0) -> 0 | D5: =IF($A5>Inputs!$F$26,1,0) -> 0 | E5: 0 | F5: 0 | G5: 0 | H5: 0 | I5: 0 | J5: 0 | K5: 0 | L5: =J5-K5 -> 0 | M5: 0 | N5: 0 | O5: =L5-N5 -> 0
A6: 1 | B6: =IF($A6>Inputs!$F$24,1,0) -> 0 | C6: =IF($A6>Inputs!$F$25,1,0) -> 0 | D6: =IF($A6>Inputs!$F$26,1,0) -> 0 | E6: =Risk_Calc!$I$5/12 -> 62500 | F6: =Risk_Calc!$I$6/12 -> 2604166.7 | G6: =Risk_Calc!$I$7/12 -> 250000 | H6: =SUM(E6:G6) -> 2916666.7 | I6: =E6*(1-Inputs!$C$24*B6)+F6*(1-Inputs!$C$25*C6)+G6*(1-Inputs!$C$26*D6) -> 2916666.7 | J6: =J5+H6 -> 2916666.7 | K6: =K5+I6 -> 2916666.7 | L6: =J6-K6 -> 0 | M6: =IF($A6=Inputs!$F$24,Inputs!$B$24,0)+IF($A6>Inputs!$F$24,Inputs!$D$24/12,0)+IF($A6=Inputs!$F$25,Inputs!$B$25,0)+IF($A6>Inputs!$F$25,Inputs!$D$25/12,0)+IF($A6=Inputs!$F$26,Inputs!$B$26,0)+IF($A6>Inputs!$F$26,Inputs!$D$26/12,0) -> 150000 | N6: =N5+M6 -> 150000 | O6: =L6-N6 -> -150000
A7: 2 | B7: =IF($A7>Inputs!$F$24,1,0) -> 0 | C7: =IF($A7>Inputs!$F$25,1,0) -> 1 | D7: =IF($A7>Inputs!$F$26,1,0) -> 0 | E7: =Risk_Calc!$I$5/12 -> 62500 | F7: =Risk_Calc!$I$6/12 -> 2604166.7 | G7: =Risk_Calc!$I$7/12 -> 250000 | H7: =SUM(E7:G7) -> 2916666.7 | I7: =E7*(1-Inputs!$C$24*B7)+F7*(1-Inputs!$C$25*C7)+G7*(1-Inputs!$C$26*D7) -> 963541.67 | J7: =J6+H7 -> 5833333.3 | K7: =K6+I7 -> 3880208.3 | L7: =J7-K7 -> 1953125 | M7: =IF($A7=Inputs!$F$24,Inputs!$B$24,0)+IF($A7>Inputs!$F$24,Inputs!$D$24/12,0)+IF($A7=Inputs!$F$25,Inputs!$B$25,0)+IF($A7>Inputs!$F$25,Inputs!$D$25/12,0)+IF($A7=Inputs!$F$26,Inputs!$B$26,0)+IF($A7>Inputs!$F$26,Inputs!$D$26/12,0) -> 2083.3333 | N7: =N6+M7 -> 152083.33 | O7: =L7-N7 -> 1801041.7
A8: 3 | B8: =IF($A8>Inputs!$F$24,1,0) -> 0 | C8: =IF($A8>Inputs!$F$25,1,0) -> 1 | D8: =IF($A8>Inputs!$F$26,1,0) -> 0 | E8: =Risk_Calc!$I$5/12 -> 62500 | F8: =Risk_Calc!$I$6/12 -> 2604166.7 | G8: =Risk_Calc!$I$7/12 -> 250000 | H8: =SUM(E8:G8) -> 2916666.7 | I8: =E8*(1-Inputs!$C$24*B8)+F8*(1-Inputs!$C$25*C8)+G8*(1-Inputs!$C$26*D8) -> 963541.67 | J8: =J7+H8 -> 8750000 | K8: =K7+I8 -> 4843750 | L8: =J8-K8 -> 3906250 | M8: =IF($A8=Inputs!$F$24,Inputs!$B$24,0)+IF($A8>Inputs!$F$24,Inputs!$D$24/12,0)+IF($A8=Inputs!$F$25,Inputs!$B$25,0)+IF($A8>Inputs!$F$25,Inputs!$D$25/12,0)+IF($A8=Inputs!$F$26,Inputs!$B$26,0)+IF($A8>Inputs!$F$26,Inputs!$D$26/12,0) -> 552083.33 | N8: =N7+M8 -> 704166.67 | O8: =L8-N8 -> 3202083.3
A9: 4 | B9: =IF($A9>Inputs!$F$24,1,0) -> 1 | C9: =IF($A9>Inputs!$F$25,1,0) -> 1 | D9: =IF($A9>Inputs!$F$26,1,0) -> 1 | E9: =Risk_Calc!$I$5/12 -> 62500 | F9: =Risk_Calc!$I$6/12 -> 2604166.7 | G9: =Risk_Calc!$I$7/12 -> 250000 | H9: =SUM(E9:G9) -> 2916666.7 | I9: =E9*(1-Inputs!$C$24*B9)+F9*(1-Inputs!$C$25*C9)+G9*(1-Inputs!$C$26*D9) -> 669791.67 | J9: =J8+H9 -> 11666667 | K9: =K8+I9 -> 5513541.7 | L9: =J9-K9 -> 6153125 | M9: =IF($A9=Inputs!$F$24,Inputs!$B$24,0)+IF($A9>Inputs!$F$24,Inputs!$D$24/12,0)+IF($A9=Inputs!$F$25,Inputs!$B$25,0)+IF($A9>Inputs!$F$25,Inputs!$D$25/12,0)+IF($A9=Inputs!$F$26,Inputs!$B$26,0)+IF($A9>Inputs!$F$26,Inputs!$D$26/12,0) -> 8750 | N9: =N8+M9 -> 712916.67 | O9: =L9-N9 -> 5440208.3
A10: 5 | B10: =IF($A10>Inputs!$F$24,1,0) -> 1 | C10: =IF($A10>Inputs!$F$25,1,0) -> 1 | D10: =IF($A10>Inputs!$F$26,1,0) -> 1 | E10: =Risk_Calc!$I$5/12 -> 62500 | F10: =Risk_Calc!$I$6/12 -> 2604166.7 | G10: =Risk_Calc!$I$7/12 -> 250000 | H10: =SUM(E10:G10) -> 2916666.7 | I10: =E10*(1-Inputs!$C$24*B10)+F10*(1-Inputs!$C$25*C10)+G10*(1-Inputs!$C$26*D10) -> 669791.67 | J10: =J9+H10 -> 14583333 | K10: =K9+I10 -> 6183333.3 | L10: =J10-K10 -> 8400000 | M10: =IF($A10=Inputs!$F$24,Inputs!$B$24,0)+IF($A10>Inputs!$F$24,Inputs!$D$24/12,0)+IF($A10=Inputs!$F$25,Inputs!$B$25,0)+IF($A10>Inputs!$F$25,Inputs!$D$25/12,0)+IF($A10=Inputs!$F$26,Inputs!$B$26,0)+IF($A10>Inputs!$F$26,Inputs!$D$26/12,0) -> 8750 | N10: =N9+M10 -> 721666.67 | O10: =L10-N10 -> 7678333.3
A11: 6 | B11: =IF($A11>Inputs!$F$24,1,0) -> 1 | C11: =IF($A11>Inputs!$F$25,1,0) -> 1 | D11: =IF($A11>Inputs!$F$26,1,0) -> 1 | E11: =Risk_Calc!$I$5/12 -> 62500 | F11: =Risk_Calc!$I$6/12 -> 2604166.7 | G11: =Risk_Calc!$I$7/12 -> 250000 | H11: =SUM(E11:G11) -> 2916666.7 | I11: =E11*(1-Inputs!$C$24*B11)+F11*(1-Inputs!$C$25*C11)+G11*(1-Inputs!$C$26*D11) -> 669791.67 | J11: =J10+H11 -> 17500000 | K11: =K10+I11 -> 6853125 | L11: =J11-K11 -> 10646875 | M11: =IF($A11=Inputs!$F$24,Inputs!$B$24,0)+IF($A11>Inputs!$F$24,Inputs!$D$24/12,0)+IF($A11=Inputs!$F$25,Inputs!$B$25,0)+IF($A11>Inputs!$F$25,Inputs!$D$25/12,0)+IF($A11=Inputs!$F$26,Inputs!$B$26,0)+IF($A11>Inputs!$F$26,Inputs!$D$26/12,0) -> 8750 | N11: =N10+M11 -> 730416.67 | O11: =L11-N11 -> 9916458.3
A12: 7 | B12: =IF($A12>Inputs!$F$24,1,0) -> 1 | C12: =IF($A12>Inputs!$F$25,1,0) -> 1 | D12: =IF($A12>Inputs!$F$26,1,0) -> 1 | E12: =Risk_Calc!$I$5/12 -> 62500 | F12: =Risk_Calc!$I$6/12 -> 2604166.7 | G12: =Risk_Calc!$I$7/12 -> 250000 | H12: =SUM(E12:G12) -> 2916666.7 | I12: =E12*(1-Inputs!$C$24*B12)+F12*(1-Inputs!$C$25*C12)+G12*(1-Inputs!$C$26*D12) -> 669791.67 | J12: =J11+H12 -> 20416667 | K12: =K11+I12 -> 7522916.7 | L12: =J12-K12 -> 12893750 | M12: =IF($A12=Inputs!$F$24,Inputs!$B$24,0)+IF($A12>Inputs!$F$24,Inputs!$D$24/12,0)+IF($A12=Inputs!$F$25,Inputs!$B$25,0)+IF($A12>Inputs!$F$25,Inputs!$D$25/12,0)+IF($A12=Inputs!$F$26,Inputs!$B$26,0)+IF($A12>Inputs!$F$26,Inputs!$D$26/12,0) -> 8750 | N12: =N11+M12 -> 739166.67 | O12: =L12-N12 -> 12154583
A13: 8 | B13: =IF($A13>Inputs!$F$24,1,0) -> 1 | C13: =IF($A13>Inputs!$F$25,1,0) -> 1 | D13: =IF($A13>Inputs!$F$26,1,0) -> 1 | E13: =Risk_Calc!$I$5/12 -> 62500 | F13: =Risk_Calc!$I$6/12 -> 2604166.7 | G13: =Risk_Calc!$I$7/12 -> 250000 | H13: =SUM(E13:G13) -> 2916666.7 | I13: =E13*(1-Inputs!$C$24*B13)+F13*(1-Inputs!$C$25*C13)+G13*(1-Inputs!$C$26*D13) -> 669791.67 | J13: =J12+H13 -> 23333333 | K13: =K12+I13 -> 8192708.3 | L13: =J13-K13 -> 15140625 | M13: =IF($A13=Inputs!$F$24,Inputs!$B$24,0)+IF($A13>Inputs!$F$24,Inputs!$D$24/12,0)+IF($A13=Inputs!$F$25,Inputs!$B$25,0)+IF($A13>Inputs!$F$25,Inputs!$D$25/12,0)+IF($A13=Inputs!$F$26,Inputs!$B$26,0)+IF($A13>Inputs!$F$26,Inputs!$D$26/12,0) -> 8750 | N13: =N12+M13 -> 747916.67 | O13: =L13-N13 -> 14392708
A14: 9 | B14: =IF($A14>Inputs!$F$24,1,0) -> 1 | C14: =IF($A14>Inputs!$F$25,1,0) -> 1 | D14: =IF($A14>Inputs!$F$26,1,0) -> 1 | E14: =Risk_Calc!$I$5/12 -> 62500 | F14: =Risk_Calc!$I$6/12 -> 2604166.7 | G14: =Risk_Calc!$I$7/12 -> 250000 | H14: =SUM(E14:G14) -> 2916666.7 | I14: =E14*(1-Inputs!$C$24*B14)+F14*(1-Inputs!$C$25*C14)+G14*(1-Inputs!$C$26*D14) -> 669791.67 | J14: =J13+H14 -> 26250000 | K14: =K13+I14 -> 8862500 | L14: =J14-K14 -> 17387500 | M14: =IF($A14=Inputs!$F$24,Inputs!$B$24,0)+IF($A14>Inputs!$F$24,Inputs!$D$24/12,0)+IF($A14=Inputs!$F$25,Inputs!$B$25,0)+IF($A14>Inputs!$F$25,Inputs!$D$25/12,0)+IF($A14=Inputs!$F$26,Inputs!$B$26,0)+IF($A14>Inputs!$F$26,Inputs!$D$26/12,0) -> 8750 | N14: =N13+M14 -> 756666.67 | O14: =L14-N14 -> 16630833
A15: 10 | B15: =IF($A15>Inputs!$F$24,1,0) -> 1 | C15: =IF($A15>Inputs!$F$25,1,0) -> 1 | D15: =IF($A15>Inputs!$F$26,1,0) -> 1 | E15: =Risk_Calc!$I$5/12 -> 62500 | F15: =Risk_Calc!$I$6/12 -> 2604166.7 | G15: =Risk_Calc!$I$7/12 -> 250000 | H15: =SUM(E15:G15) -> 2916666.7 | I15: =E15*(1-Inputs!$C$24*B15)+F15*(1-Inputs!$C$25*C15)+G15*(1-Inputs!$C$26*D15) -> 669791.67 | J15: =J14+H15 -> 29166667 | K15: =K14+I15 -> 9532291.7 | L15: =J15-K15 -> 19634375 | M15: =IF($A15=Inputs!$F$24,Inputs!$B$24,0)+IF($A15>Inputs!$F$24,Inputs!$D$24/12,0)+IF($A15=Inputs!$F$25,Inputs!$B$25,0)+IF($A15>Inputs!$F$25,Inputs!$D$25/12,0)+IF($A15=Inputs!$F$26,Inputs!$B$26,0)+IF($A15>Inputs!$F$26,Inputs!$D$26/12,0) -> 8750 | N15: =N14+M15 -> 765416.67 | O15: =L15-N15 -> 18868958
A16: 11 | B16: =IF($A16>Inputs!$F$24,1,0) -> 1 | C16: =IF($A16>Inputs!$F$25,1,0) -> 1 | D16: =IF($A16>Inputs!$F$26,1,0) -> 1 | E16: =Risk_Calc!$I$5/12 -> 62500 | F16: =Risk_Calc!$I$6/12 -> 2604166.7 | G16: =Risk_Calc!$I$7/12 -> 250000 | H16: =SUM(E16:G16) -> 2916666.7 | I16: =E16*(1-Inputs!$C$24*B16)+F16*(1-Inputs!$C$25*C16)+G16*(1-Inputs!$C$26*D16) -> 669791.67 | J16: =J15+H16 -> 32083333 | K16: =K15+I16 -> 10202083 | L16: =J16-K16 -> 21881250 | M16: =IF($A16=Inputs!$F$24,Inputs!$B$24,0)+IF($A16>Inputs!$F$24,Inputs!$D$24/12,0)+IF($A16=Inputs!$F$25,Inputs!$B$25,0)+IF($A16>Inputs!$F$25,Inputs!$D$25/12,0)+IF($A16=Inputs!$F$26,Inputs!$B$26,0)+IF($A16>Inputs!$F$26,Inputs!$D$26/12,0) -> 8750 | N16: =N15+M16 -> 774166.67 | O16: =L16-N16 -> 21107083
A17: 12 | B17: =IF($A17>Inputs!$F$24,1,0) -> 1 | C17: =IF($A17>Inputs!$F$25,1,0) -> 1 | D17: =IF($A17>Inputs!$F$26,1,0) -> 1 | E17: =Risk_Calc!$I$5/12 -> 62500 | F17: =Risk_Calc!$I$6/12 -> 2604166.7 | G17: =Risk_Calc!$I$7/12 -> 250000 | H17: =SUM(E17:G17) -> 2916666.7 | I17: =E17*(1-Inputs!$C$24*B17)+F17*(1-Inputs!$C$25*C17)+G17*(1-Inputs!$C$26*D17) -> 669791.67 | J17: =J16+H17 -> 35000000 | K17: =K16+I17 -> 10871875 | L17: =J17-K17 -> 24128125 | M17: =IF($A17=Inputs!$F$24,Inputs!$B$24,0)+IF($A17>Inputs!$F$24,Inputs!$D$24/12,0)+IF($A17=Inputs!$F$25,Inputs!$B$25,0)+IF($A17>Inputs!$F$25,Inputs!$D$25/12,0)+IF($A17=Inputs!$F$26,Inputs!$B$26,0)+IF($A17>Inputs!$F$26,Inputs!$D$26/12,0) -> 8750 | N17: =N16+M17 -> 782916.67 | O17: =L17-N17 -> 23345208
A19: Month 12 summary
A20: Year-1 expected loss with NO controls | D20: =J17 -> 35000000
A21: Year-1 expected loss WITH phased controls | D21: =K17 -> 10871875
A22: Year-1 loss avoided (phased roll-out) | D22: =D20-D21 -> 24128125
A23: Year-1 control spend (initial + maintenance after go-live) | D23: =N17 -> 782916.67
A24: Year-1 net benefit after control spend | D24: =D22-D23 -> 23345208
A25: Steady-state annual risk reduction (Control_Analysis, once all controls are live) | D25: =Control_Analysis!F8 -> 26962500
A27: Why Year-1 avoided loss (row 22) is lower than steady-state reduction (row 25): controls only go live on days 30 and 90, so part of Year 1 is unprotected.

Sheet Gantt
A1: Task 7 – Risk treatment plan (Gantt chart)
A2: Start day and duration are editable planning assumptions (blue/yellow). End day = Start + Duration − 1. Each coloured block = a 15-day window in which the task is active.
H3: Day window starts →
A4: # | B4: Phase | C4: Task | D4: Start day | E4: Duration (days) | F4: End day | G4: Owner (assumed) | H4: 1 | I4: =H4+15 -> 16 | J4: =I4+15 -> 31 | K4: =J4+15 -> 46 | L4: =K4+15 -> 61 | M4: =L4+15 -> 76 | N4: =M4+15 -> 91 | O4: =N4+15 -> 106 | P4: =O4+15 -> 121 | ... AF4: =AE4+15 -> 361
A5: 1 | B5: 1 Immediate (days 1-30) | C5: Risk acceptance briefing and funding approval (CISO / CFO) | D5: 1 | E5: 7 | F5: =D5+E5-1 -> 7 | G5: CISO / CFO
A6: 2 | B6: 1 Immediate (days 1-30) | C6: Emergency mitigations: session timeout & token rotation, API auth hotfix review, input validation rules | D6: 1 | E6: 21 | F6: =D6+E6-1 -> 21 | G6: App Sec / DevOps
A7: 3 | B7: 1 Immediate (days 1-30) | C7: WAF procurement, deployment and tuning (virtual patch for database injection) | D7: 8 | E7: 23 | F7: =D7+E7-1 -> 30 | G7: Infrastructure / SecOps
A8: 4 | B8: 1 Immediate (days 1-30) | C8: Enhanced API and session monitoring and alerting (shorten 48-hour detection) | D8: 8 | E8: 23 | F8: =D8+E8-1 -> 30 | G8: SOC
A9: 5 | B9: 2 Short-term (days 31-90) | C9: MFA enhancement: design, procurement and pilot | D9: 31 | E9: 30 | F9: =D9+E9-1 -> 60 | G9: IAM team
A10: 6 | B10: 2 Short-term (days 31-90) | C10: MFA enhancement: full rollout to all customers | D10: 61 | E10: 30 | F10: =D10+E10-1 -> 90 | G10: IAM / Mobile team
A11: 7 | B11: 2 Short-term (days 31-90) | C11: API Security Gateway: procurement and integration | D11: 31 | E11: 45 | F11: =D11+E11-1 -> 75 | G11: Platform / App Sec
A12: 8 | B12: 2 Short-term (days 31-90) | C12: API Security Gateway: cut-over and acceptance testing | D12: 76 | E12: 15 | F12: =D12+E12-1 -> 90 | G12: Platform / QA
A13: 9 | B13: 2 Short-term (days 31-90) | C13: Penetration re-test of the three critical findings | D13: 80 | E13: 11 | F13: =D13+E13-1 -> 90 | G13: Red team / third party
A14: 10 | B14: 3 Long-term (days 91-365) | C14: Root-cause remediation in code (parameterised queries, session management, API auth design) | D14: 91 | E14: 150 | F14: =D14+E14-1 -> 240 | G14: Engineering
A15: 11 | B15: 3 Long-term (days 91-365) | C15: Control effectiveness review and ALE re-assessment | D15: 180 | E15: 30 | F15: =D15+E15-1 -> 209 | G15: GRC
A16: 12 | B16: 3 Long-term (days 91-365) | C16: Continuous monitoring, quarterly testing and risk register updates | D16: 91 | E16: 275 | F16: =D16+E16-1 -> 365 | G16: GRC / SOC
A17: 13 | B17: 3 Long-term (days 91-365) | C17: Annual re-test and board report on residual risk | D17: 335 | E17: 31 | F17: =D17+E17-1 -> 365 | G17: CISO / GRC
A19: Legend: red = Immediate actions (first 30 days); orange = Short-term controls (to day 90); blue = Long-term strategy (to day 365).
A20: Go-live logic: WAF is live when task 3 ends (day 30); MFA when task 6 ends and API Gateway when task 8 ends (day 90). These feed Inputs!F24:F26 and the Timeline sheet.

Sheet Budget_Optimiser
A1: Bonus – Optimal control selection under budget constraints
A2: All 8 combinations of the 3 controls are evaluated (1 = included). For each budget the feasible combination with the largest annual risk reduction is chosen.
A4: # | B4: Combination | C4: API Gateway (1/0) | D4: WAF (1/0) | E4: MFA (1/0) | F4: Capital cost ($) | G4: Annual risk reduction ($) | H4: Annual maintenance ($) | I4: Residual ALE ($) | J4: Year-1 ROI (%)
A5: 1 | B5: None | C5: 0 | D5: 0 | E5: 0 | F5: =C5*Control_Analysis!$C$10+D5*Control_Analysis!$D$10+E5*Control_Analysis!$E$10 -> 0 | G5: =C5*Control_Analysis!$C$8+D5*Control_Analysis!$D$8+E5*Control_Analysis!$E$8 -> 0 | H5: =C5*Control_Analysis!$C$11+D5*Control_Analysis!$D$11+E5*Control_Analysis!$E$11 -> 0 | I5: =Control_Analysis!$F$6-G5 -> 35000000 | J5: =IF(F5+H5=0,0,(G5-F5-H5)/(F5+H5)) -> 0
A6: 2 | B6: API Gateway | C6: 1 | D6: 0 | E6: 0 | F6: =C6*Control_Analysis!$C$10+D6*Control_Analysis!$D$10+E6*Control_Analysis!$E$10 -> 350000 | G6: =C6*Control_Analysis!$C$8+D6*Control_Analysis!$D$8+E6*Control_Analysis!$E$8 -> 675000 | H6: =C6*Control_Analysis!$C$11+D6*Control_Analysis!$D$11+E6*Control_Analysis!$E$11 -> 50000 | I6: =Control_Analysis!$F$6-G6 -> 34325000 | J6: =IF(F6+H6=0,0,(G6-F6-H6)/(F6+H6)) -> 0.6875
A7: 3 | B7: WAF | C7: 0 | D7: 1 | E7: 0 | F7: =C7*Control_Analysis!$C$10+D7*Control_Analysis!$D$10+E7*Control_Analysis!$E$10 -> 150000 | G7: =C7*Control_Analysis!$C$8+D7*Control_Analysis!$D$8+E7*Control_Analysis!$E$8 -> 23437500 | H7: =C7*Control_Analysis!$C$11+D7*Control_Analysis!$D$11+E7*Control_Analysis!$E$11 -> 25000 | I7: =Control_Analysis!$F$6-G7 -> 11562500 | J7: =IF(F7+H7=0,0,(G7-F7-H7)/(F7+H7)) -> 132.92857
A8: 4 | B8: MFA | C8: 0 | D8: 0 | E8: 1 | F8: =C8*Control_Analysis!$C$10+D8*Control_Analysis!$D$10+E8*Control_Analysis!$E$10 -> 200000 | G8: =C8*Control_Analysis!$C$8+D8*Control_Analysis!$D$8+E8*Control_Analysis!$E$8 -> 2850000 | H8: =C8*Control_Analysis!$C$11+D8*Control_Analysis!$D$11+E8*Control_Analysis!$E$11 -> 30000 | I8: =Control_Analysis!$F$6-G8 -> 32150000 | J8: =IF(F8+H8=0,0,(G8-F8-H8)/(F8+H8)) -> 11.391304
A9: 5 | B9: API Gateway + WAF | C9: 1 | D9: 1 | E9: 0 | F9: =C9*Control_Analysis!$C$10+D9*Control_Analysis!$D$10+E9*Control_Analysis!$E$10 -> 500000 | G9: =C9*Control_Analysis!$C$8+D9*Control_Analysis!$D$8+E9*Control_Analysis!$E$8 -> 24112500 | H9: =C9*Control_Analysis!$C$11+D9*Control_Analysis!$D$11+E9*Control_Analysis!$E$11 -> 75000 | I9: =Control_Analysis!$F$6-G9 -> 10887500 | J9: =IF(F9+H9=0,0,(G9-F9-H9)/(F9+H9)) -> 40.934783
A10: 6 | B10: API Gateway + MFA | C10: 1 | D10: 0 | E10: 1 | F10: =C10*Control_Analysis!$C$10+D10*Control_Analysis!$D$10+E10*Control_Analysis!$E$10 -> 550000 | G10: =C10*Control_Analysis!$C$8+D10*Control_Analysis!$D$8+E10*Control_Analysis!$E$8 -> 3525000 | H10: =C10*Control_Analysis!$C$11+D10*Control_Analysis!$D$11+E10*Control_Analysis!$E$11 -> 80000 | I10: =Control_Analysis!$F$6-G10 -> 31475000 | J10: =IF(F10+H10=0,0,(G10-F10-H10)/(F10+H10)) -> 4.5952381
A11: 7 | B11: WAF + MFA | C11: 0 | D11: 1 | E11: 1 | F11: =C11*Control_Analysis!$C$10+D11*Control_Analysis!$D$10+E11*Control_Analysis!$E$10 -> 350000 | G11: =C11*Control_Analysis!$C$8+D11*Control_Analysis!$D$8+E11*Control_Analysis!$E$8 -> 26287500 | H11: =C11*Control_Analysis!$C$11+D11*Control_Analysis!$D$11+E11*Control_Analysis!$E$11 -> 55000 | I11: =Control_Analysis!$F$6-G11 -> 8712500 | J11: =IF(F11+H11=0,0,(G11-F11-H11)/(F11+H11)) -> 63.907407
A12: 8 | B12: API Gateway + WAF + MFA | C12: 1 | D12: 1 | E12: 1 | F12: =C12*Control_Analysis!$C$10+D12*Control_Analysis!$D$10+E12*Control_Analysis!$E$10 -> 700000 | G12: =C12*Control_Analysis!$C$8+D12*Control_Analysis!$D$8+E12*Control_Analysis!$E$8 -> 26962500 | H12: =C12*Control_Analysis!$C$11+D12*Control_Analysis!$D$11+E12*Control_Analysis!$E$11 -> 105000 | I12: =Control_Analysis!$F$6-G12 -> 8037500 | J12: =IF(F12+H12=0,0,(G12-F12-H12)/(F12+H12)) -> 32.493789
A15: Budget scenarios (capital budget is an assumption – edit the yellow cells)
A16: Scenario | B16: Capital budget ($) | C16: Best feasible annual risk reduction ($) | D16: Recommended combination | E16: Capital used ($) | F16: Residual ALE ($) | G16: Risk reduced (% of baseline ALE)
A17: Budget 1 | B17: 150000 | C17: =SUMPRODUCT(MAX(($F$5:$F$12<=B17)*$G$5:$G$12)) -> 23437500 | D17: =INDEX($B$5:$B$12,MATCH(C17,$G$5:$G$12,0)) -> WAF | E17: =INDEX($F$5:$F$12,MATCH(C17,$G$5:$G$12,0)) -> 150000 | F17: =Control_Analysis!$F$6-C17 -> 11562500 | G17: =C17/Control_Analysis!$F$6 -> 0.66964286
A18: Budget 2 | B18: 350000 | C18: =SUMPRODUCT(MAX(($F$5:$F$12<=B18)*$G$5:$G$12)) -> 26287500 | D18: =INDEX($B$5:$B$12,MATCH(C18,$G$5:$G$12,0)) -> WAF + MFA | E18: =INDEX($F$5:$F$12,MATCH(C18,$G$5:$G$12,0)) -> 350000 | F18: =Control_Analysis!$F$6-C18 -> 8712500 | G18: =C18/Control_Analysis!$F$6 -> 0.75107143
A19: Budget 3 | B19: 500000 | C19: =SUMPRODUCT(MAX(($F$5:$F$12<=B19)*$G$5:$G$12)) -> 26287500 | D19: =INDEX($B$5:$B$12,MATCH(C19,$G$5:$G$12,0)) -> WAF + MFA | E19: =INDEX($F$5:$F$12,MATCH(C19,$G$5:$G$12,0)) -> 350000 | F19: =Control_Analysis!$F$6-C19 -> 8712500 | G19: =C19/Control_Analysis!$F$6 -> 0.75107143
A20: Budget 4 | B20: 700000 | C20: =SUMPRODUCT(MAX(($F$5:$F$12<=B20)*$G$5:$G$12)) -> 26962500 | D20: =INDEX($B$5:$B$12,MATCH(C20,$G$5:$G$12,0)) -> API Gateway + WAF + MFA | E20: =INDEX($F$5:$F$12,MATCH(C20,$G$5:$G$12,0)) -> 700000 | F20: =Control_Analysis!$F$6-C20 -> 8037500 | G20: =C20/Control_Analysis!$F$6 -> 0.77035714
A22: Reading: at the smallest budget the WAF alone captures most of the reduction; each extra control adds a smaller benefit. Budget refers to initial capital cost only (assumption A-14).

Sheet Sensitivity
A1: Sensitivity – how wrong can the assumptions be before a control stops paying back?
A2: Break-even ALE = Year-1 cost ÷ effectiveness. Below that baseline ALE, the control's Year-1 benefit is smaller than its Year-1 cost.
A4: Control | B4: Year-1 cost ($) | C4: Effectiveness | D4: Break-even baseline ALE ($/yr) | E4: Modelled baseline ALE ($/yr) | F4: Headroom (x) | G4: Break-even as % of modelled ALE
A5: =Control_Analysis!C4 -> Advanced API Security Gateway | B5: =Control_Analysis!C12 -> 400000 | C5: =Control_Analysis!C7 -> 0.9 | D5: =B5/C5 -> 444444.44 | E5: =Control_Analysis!C6 -> 750000 | F5: =E5/D5 -> 1.6875 | G5: =D5/E5 -> 0.59259259
A6: =Control_Analysis!D4 -> Web Application Firewall (WAF) | B6: =Control_Analysis!D12 -> 175000 | C6: =Control_Analysis!D7 -> 0.75 | D6: =B6/C6 -> 233333.33 | E6: =Control_Analysis!D6 -> 31250000 | F6: =E6/D6 -> 133.92857 | G6: =D6/E6 -> 0.0074666667
A7: =Control_Analysis!E4 -> Multi-Factor Authentication Enhancement | B7: =Control_Analysis!E12 -> 230000 | C7: =Control_Analysis!E7 -> 0.95 | D7: =B7/C7 -> 242105.26 | E7: =Control_Analysis!E6 -> 3000000 | F7: =E7/D7 -> 12.391304 | G7: =D7/E7 -> 0.080701754
A10: Table 2 – WAF Year-1 ROI if the database breach is smaller and/or less likely than modelled
A11: Share of 500k records breached ↓ / F2 probability → | B11: 0.25 | C11: 0.15 | D11: 0.1 | E11: 0.05 | F11: 0.01
A12: 1 | B12: =(Inputs!$B$16*$A12*Inputs!$B$17*B$11*Inputs!$C$25-Control_Analysis!$D$12)/Control_Analysis!$D$12 -> 132.92857 | C12: =(Inputs!$B$16*$A12*Inputs!$B$17*C$11*Inputs!$C$25-Control_Analysis!$D$12)/Control_Analysis!$D$12 -> 79.357143 | D12: =(Inputs!$B$16*$A12*Inputs!$B$17*D$11*Inputs!$C$25-Control_Analysis!$D$12)/Control_Analysis!$D$12 -> 52.571429 | E12: =(Inputs!$B$16*$A12*Inputs!$B$17*E$11*Inputs!$C$25-Control_Analysis!$D$12)/Control_Analysis!$D$12 -> 25.785714 | F12: =(Inputs!$B$16*$A12*Inputs!$B$17*F$11*Inputs!$C$25-Control_Analysis!$D$12)/Control_Analysis!$D$12 -> 4.3571429
A13: 0.5 | B13: =(Inputs!$B$16*$A13*Inputs!$B$17*B$11*Inputs!$C$25-Control_Analysis!$D$12)/Control_Analysis!$D$12 -> 65.964286 | C13: =(Inputs!$B$16*$A13*Inputs!$B$17*C$11*Inputs!$C$25-Control_Analysis!$D$12)/Control_Analysis!$D$12 -> 39.178571 | D13: =(Inputs!$B$16*$A13*Inputs!$B$17*D$11*Inputs!$C$25-Control_Analysis!$D$12)/Control_Analysis!$D$12 -> 25.785714 | E13: =(Inputs!$B$16*$A13*Inputs!$B$17*E$11*Inputs!$C$25-Control_Analysis!$D$12)/Control_Analysis!$D$12 -> 12.392857 | F13: =(Inputs!$B$16*$A13*Inputs!$B$17*F$11*Inputs!$C$25-Control_Analysis!$D$12)/Control_Analysis!$D$12 -> 1.6785714
A14: 0.25 | B14: =(Inputs!$B$16*$A14*Inputs!$B$17*B$11*Inputs!$C$25-Control_Analysis!$D$12)/Control_Analysis!$D$12 -> 32.482143 | C14: =(Inputs!$B$16*$A14*Inputs!$B$17*C$11*Inputs!$C$25-Control_Analysis!$D$12)/Control_Analysis!$D$12 -> 19.089286 | D14: =(Inputs!$B$16*$A14*Inputs!$B$17*D$11*Inputs!$C$25-Control_Analysis!$D$12)/Control_Analysis!$D$12 -> 12.392857 | E14: =(Inputs!$B$16*$A14*Inputs!$B$17*E$11*Inputs!$C$25-Control_Analysis!$D$12)/Control_Analysis!$D$12 -> 5.6964286 | F14: =(Inputs!$B$16*$A14*Inputs!$B$17*F$11*Inputs!$C$25-Control_Analysis!$D$12)/Control_Analysis!$D$12 -> 0.33928571
A15: 0.1 | B15: =(Inputs!$B$16*$A15*Inputs!$B$17*B$11*Inputs!$C$25-Control_Analysis!$D$12)/Control_Analysis!$D$12 -> 12.392857 | C15: =(Inputs!$B$16*$A15*Inputs!$B$17*C$11*Inputs!$C$25-Control_Analysis!$D$12)/Control_Analysis!$D$12 -> 7.0357143 | D15: =(Inputs!$B$16*$A15*Inputs!$B$17*D$11*Inputs!$C$25-Control_Analysis!$D$12)/Control_Analysis!$D$12 -> 4.3571429 | E15: =(Inputs!$B$16*$A15*Inputs!$B$17*E$11*Inputs!$C$25-Control_Analysis!$D$12)/Control_Analysis!$D$12 -> 1.6785714 | F15: =(Inputs!$B$16*$A15*Inputs!$B$17*F$11*Inputs!$C$25-Control_Analysis!$D$12)/Control_Analysis!$D$12 -> -0.46428571
A16: 0.05 | B16: =(Inputs!$B$16*$A16*Inputs!$B$17*B$11*Inputs!$C$25-Control_Analysis!$D$12)/Control_Analysis!$D$12 -> 5.6964286 | C16: =(Inputs!$B$16*$A16*Inputs!$B$17*C$11*Inputs!$C$25-Control_Analysis!$D$12)/Control_Analysis!$D$12 -> 3.0178571 | D16: =(Inputs!$B$16*$A16*Inputs!$B$17*D$11*Inputs!$C$25-Control_Analysis!$D$12)/Control_Analysis!$D$12 -> 1.6785714 | E16: =(Inputs!$B$16*$A16*Inputs!$B$17*E$11*Inputs!$C$25-Control_Analysis!$D$12)/Control_Analysis!$D$12 -> 0.33928571 | F16: =(Inputs!$B$16*$A16*Inputs!$B$17*F$11*Inputs!$C$25-Control_Analysis!$D$12)/Control_Analysis!$D$12 -> -0.73214286
A19: Table 3 – API Gateway Year-1 ROI if the loss per event and/or probability are lower than modelled (the marginal control)
A20: Loss per event ($) ↓ / F1 probability → | B20: 0.15 | C20: 0.12 | D20: 0.1 | E20: 0.08 | F20: 0.05
A21: 5000000 | B21: =($A21*Inputs!$B$39*B$20*Inputs!$C$24-Control_Analysis!$C$12)/Control_Analysis!$C$12 -> 0.6875 | C21: =($A21*Inputs!$B$39*C$20*Inputs!$C$24-Control_Analysis!$C$12)/Control_Analysis!$C$12 -> 0.35 | D21: =($A21*Inputs!$B$39*D$20*Inputs!$C$24-Control_Analysis!$C$12)/Control_Analysis!$C$12 -> 0.125 | E21: =($A21*Inputs!$B$39*E$20*Inputs!$C$24-Control_Analysis!$C$12)/Control_Analysis!$C$12 -> -0.1 | F21: =($A21*Inputs!$B$39*F$20*Inputs!$C$24-Control_Analysis!$C$12)/Control_Analysis!$C$12 -> -0.4375
A22: 4000000 | B22: =($A22*Inputs!$B$39*B$20*Inputs!$C$24-Control_Analysis!$C$12)/Control_Analysis!$C$12 -> 0.35 | C22: =($A22*Inputs!$B$39*C$20*Inputs!$C$24-Control_Analysis!$C$12)/Control_Analysis!$C$12 -> 0.08 | D22: =($A22*Inputs!$B$39*D$20*Inputs!$C$24-Control_Analysis!$C$12)/Control_Analysis!$C$12 -> -0.1 | E22: =($A22*Inputs!$B$39*E$20*Inputs!$C$24-Control_Analysis!$C$12)/Control_Analysis!$C$12 -> -0.28 | F22: =($A22*Inputs!$B$39*F$20*Inputs!$C$24-Control_Analysis!$C$12)/Control_Analysis!$C$12 -> -0.55
A23: 3000000 | B23: =($A23*Inputs!$B$39*B$20*Inputs!$C$24-Control_Analysis!$C$12)/Control_Analysis!$C$12 -> 0.0125 | C23: =($A23*Inputs!$B$39*C$20*Inputs!$C$24-Control_Analysis!$C$12)/Control_Analysis!$C$12 -> -0.19 | D23: =($A23*Inputs!$B$39*D$20*Inputs!$C$24-Control_Analysis!$C$12)/Control_Analysis!$C$12 -> -0.325 | E23: =($A23*Inputs!$B$39*E$20*Inputs!$C$24-Control_Analysis!$C$12)/Control_Analysis!$C$12 -> -0.46 | F23: =($A23*Inputs!$B$39*F$20*Inputs!$C$24-Control_Analysis!$C$12)/Control_Analysis!$C$12 -> -0.6625
A24: 2000000 | B24: =($A24*Inputs!$B$39*B$20*Inputs!$C$24-Control_Analysis!$C$12)/Control_Analysis!$C$12 -> -0.325 | C24: =($A24*Inputs!$B$39*C$20*Inputs!$C$24-Control_Analysis!$C$12)/Control_Analysis!$C$12 -> -0.46 | D24: =($A24*Inputs!$B$39*D$20*Inputs!$C$24-Control_Analysis!$C$12)/Control_Analysis!$C$12 -> -0.55 | E24: =($A24*Inputs!$B$39*E$20*Inputs!$C$24-Control_Analysis!$C$12)/Control_Analysis!$C$12 -> -0.64 | F24: =($A24*Inputs!$B$39*F$20*Inputs!$C$24-Control_Analysis!$C$12)/Control_Analysis!$C$12 -> -0.775
A26: Red / bracketed values = negative Year-1 ROI. The WAF stays positive in every cell of Table 2; the API Gateway turns negative when its ALE falls below about $444k, so it is the control most sensitive to the assumptions.

Sheet Chart_Data
A1: Chart data (linked – do not type over)
A4: Vulnerability | B4: ALE before controls ($) | C4: ALE after controls ($) | D4: Share of total ALE
A5: =Risk_Calc!B5 -> F1 – API Authentication Bypass | B5: =Risk_Calc!I5 -> 750000 | C5: =B5-SUMPRODUCT((Control_Analysis!$C$5:$E$5=Risk_Calc!A5)*Control_Analysis!$C$8:$E$8) -> 75000 | D5: =Risk_Calc!J5 -> 0.021428571
A6: =Risk_Calc!B6 -> F2 – Database Injection Vulnerability | B6: =Risk_Calc!I6 -> 31250000 | C6: =B6-SUMPRODUCT((Control_Analysis!$C$5:$E$5=Risk_Calc!A6)*Control_Analysis!$C$8:$E$8) -> 7812500 | D6: =Risk_Calc!J6 -> 0.89285714
A7: =Risk_Calc!B7 -> F3 – Session Hijacking | B7: =Risk_Calc!I7 -> 3000000 | C7: =B7-SUMPRODUCT((Control_Analysis!$C$5:$E$5=Risk_Calc!A7)*Control_Analysis!$C$8:$E$8) -> 150000 | D7: =Risk_Calc!J7 -> 0.085714286
A11: Control | B11: Initial investment ($) | C11: Maintenance over horizon ($) | D11: Year-1 cost ($) | E11: Effectiveness (%) | F11: Annual risk reduction ($) | G11: Year-1 ROI (%) | H11: 3-year ROI (%) | I11: Payback (months) | J11: Control (short label) | K11: Year-1 ROI (%)
A12: =Control_Analysis!C4 -> Advanced API Security Gateway | B12: =Control_Analysis!C10 -> 350000 | C12: =Control_Analysis!C11*Inputs!$B$28 -> 150000 | D12: =Control_Analysis!C12 -> 400000 | E12: =Control_Analysis!C7 -> 0.9 | F12: =Control_Analysis!C8 -> 675000 | G12: =Control_Analysis!C14 -> 0.6875 | H12: =Control_Analysis!C18 -> 3.05 | I12: =Control_Analysis!C20 -> 6.72 | J12: API Gateway | K12: =G12*100 -> 68.75
A13: =Control_Analysis!D4 -> Web Application Firewall (WAF) | B13: =Control_Analysis!D10 -> 150000 | C13: =Control_Analysis!D11*Inputs!$B$28 -> 75000 | D13: =Control_Analysis!D12 -> 175000 | E13: =Control_Analysis!D7 -> 0.75 | F13: =Control_Analysis!D8 -> 23437500 | G13: =Control_Analysis!D14 -> 132.92857 | H13: =Control_Analysis!D18 -> 311.5 | I13: =Control_Analysis!D20 -> 0.076882007 | J13: WAF | K13: =G13*100 -> 13292.857
A14: =Control_Analysis!E4 -> Multi-Factor Authentication Enhancement | B14: =Control_Analysis!E10 -> 200000 | C14: =Control_Analysis!E11*Inputs!$B$28 -> 90000 | D14: =Control_Analysis!E12 -> 230000 | E14: =Control_Analysis!E7 -> 0.95 | F14: =Control_Analysis!E8 -> 2850000 | G14: =Control_Analysis!E14 -> 11.391304 | H14: =Control_Analysis!E18 -> 28.482759 | I14: =Control_Analysis!E20 -> 0.85106383 | J14: MFA | K14: =G14*100 -> 1139.1304
J15: Column K = column G × 100, so the log-scale ROI charts plot every bar above 1.
A19: Gantt chart data (stacked bar = invisible start offset + duration coloured by phase)
A20: Task (short label) | B20: Start offset (start day − 1) | C20: Immediate actions (days 1-30) | D20: Short-term controls (to day 90) | E20: Long-term strategy (to day 365)
A21: 1 Funding approval briefing | B21: =Gantt!D5-1 -> 0 | C21: =IF(LEFT(Gantt!B5,1)="1",Gantt!E5,0) -> 7 | D21: =IF(LEFT(Gantt!B5,1)="2",Gantt!E5,0) -> 0 | E21: =IF(LEFT(Gantt!B5,1)="3",Gantt!E5,0) -> 0
A22: 2 Emergency mitigations | B22: =Gantt!D6-1 -> 0 | C22: =IF(LEFT(Gantt!B6,1)="1",Gantt!E6,0) -> 21 | D22: =IF(LEFT(Gantt!B6,1)="2",Gantt!E6,0) -> 0 | E22: =IF(LEFT(Gantt!B6,1)="3",Gantt!E6,0) -> 0
A23: 3 WAF deploy and tune | B23: =Gantt!D7-1 -> 7 | C23: =IF(LEFT(Gantt!B7,1)="1",Gantt!E7,0) -> 23 | D23: =IF(LEFT(Gantt!B7,1)="2",Gantt!E7,0) -> 0 | E23: =IF(LEFT(Gantt!B7,1)="3",Gantt!E7,0) -> 0
A24: 4 API / session monitoring | B24: =Gantt!D8-1 -> 7 | C24: =IF(LEFT(Gantt!B8,1)="1",Gantt!E8,0) -> 23 | D24: =IF(LEFT(Gantt!B8,1)="2",Gantt!E8,0) -> 0 | E24: =IF(LEFT(Gantt!B8,1)="3",Gantt!E8,0) -> 0
A25: 5 MFA design and pilot | B25: =Gantt!D9-1 -> 30 | C25: =IF(LEFT(Gantt!B9,1)="1",Gantt!E9,0) -> 0 | D25: =IF(LEFT(Gantt!B9,1)="2",Gantt!E9,0) -> 30 | E25: =IF(LEFT(Gantt!B9,1)="3",Gantt!E9,0) -> 0
A26: 6 MFA full rollout | B26: =Gantt!D10-1 -> 60 | C26: =IF(LEFT(Gantt!B10,1)="1",Gantt!E10,0) -> 0 | D26: =IF(LEFT(Gantt!B10,1)="2",Gantt!E10,0) -> 30 | E26: =IF(LEFT(Gantt!B10,1)="3",Gantt!E10,0) -> 0
A27: 7 API Gateway integration | B27: =Gantt!D11-1 -> 30 | C27: =IF(LEFT(Gantt!B11,1)="1",Gantt!E11,0) -> 0 | D27: =IF(LEFT(Gantt!B11,1)="2",Gantt!E11,0) -> 45 | E27: =IF(LEFT(Gantt!B11,1)="3",Gantt!E11,0) -> 0
A28: 8 API Gateway cut-over | B28: =Gantt!D12-1 -> 75 | C28: =IF(LEFT(Gantt!B12,1)="1",Gantt!E12,0) -> 0 | D28: =IF(LEFT(Gantt!B12,1)="2",Gantt!E12,0) -> 15 | E28: =IF(LEFT(Gantt!B12,1)="3",Gantt!E12,0) -> 0
A29: 9 Penetration re-test | B29: =Gantt!D13-1 -> 79 | C29: =IF(LEFT(Gantt!B13,1)="1",Gantt!E13,0) -> 0 | D29: =IF(LEFT(Gantt!B13,1)="2",Gantt!E13,0) -> 11 | E29: =IF(LEFT(Gantt!B13,1)="3",Gantt!E13,0) -> 0
